Workbook

Sheet Example
A1: This example started as a test workbook. I think I removed all negative testing and everything that doesn't make sense while keeping as many examples as possible. It is not intended to illustrate best practice or make recommendations.
A3: The assumption is that all logical switches, other than the default switch, are being created. Several of the switch definitions and some of the port definitions require the switch or port to be disabled. If the switches and ports are already enabled, running switch_config.py with this workbook will generate errors for those items that require the switch or port to be offline, but it should continue running and make whatever changes can be made.
A5: Setting the DID on the "slot x" Worksheets to Match the "Switch_x" Worksheet
A6: Setting the DID on the "Slot x" worksheets isn’t as simple as setting the DID to the DID on the corresponding “Switch_x” worksheet. See cell Slot 0!C131 as an example of how to set the DID to match a DID in the “Switch_x” worksheet.
A8: Port Naming Convention
A9: The port naming convention is discretionary. Four different naming conventions are used for the purpose of providing examples only.
A11: Switch_128
A12: The default switch, "Switch_128", did not have insistent domain ID set. Even though the DID is not changing, setting it to insistent requires the switch to be disabled. This example shows how to disable the switch, set insistent DID, and then re-enable it. It also serves as an example on how to persistently disable ports.
A14: Switch_Open
A15: This is the typical configuration for an open systems switch that has storage with automatic failover. "Allow XISL" is set as an example on how to configure a switch for use with a base switch.
A17: Switch_FICON
A18: Use of the control unit port (CUP) is common in FICON environments. "Enable CUP" therefore is typically "Yes", but I didn't have a CUP license on the test switch I used for this, so it is set to "No". All other settings are typical for FICON switches.
... A26: Except for the CLI in the base switch, these are typical settings.

Sheet Instructions
A1: Intended for use with switcy_config.py and switcy_config_cli.py.
A3: Step 1
A4: Make a copy of this workbook
A6: Step 2
A7: Define the chassis parameters on the "Chassis" sheet.
A9: Step 3
A10: Define the switch(es) using the "Switch_x" sheet. Make copies of this sheet to define multiple switches. All sheet names beginning with "Switch_" are assumed to be a switch configuration worksheet. The "x" in tab name is only used so that Excel has unique sheet names. Typically, x is replaced with the FID number or user-friendly switch name, but it is not used by scripts that read this workbook. It can be whatever you want. Keep in mind that most of the switch configuration items require the switch to be disabled. When switches are newly created, they are disabled.
A12: Step 4
A13: Fill out the "Slot 0" Worksheet. See the "Slot_x_Terms" tab for details. Only ports with a FID that matches a FID on a “Switch_x” worksheet are acted on. All other ports are ignored.
A15: Command Line Options
A16: -force | B16: Disables are only performed when -force is specified. Keep in mind the CLI is not interpreted. Although not recommended, you can disabled something with a CLI command.
A18: -cli | B18: CLI is only executed if -cli is specified. CLI is always executed when -cli is specified. CLI commands are executed as is. There is no ability to respond to interactive CLI commands. For error reporting purposes, some basic parsing of CLI responses are performed, but administrators should be aware that several error conditions are not processed. This means you can do whatever you want with CLI commands. Just keep in mind that just because you can do whatever you want, that doesn't mean you want to do whatever you can do.
A21: Best Effort
A22: A best effort algorithm is applied. Errors are reported as they are encountered, but processing continues.
A24: FICON Tip
A25: When possible, the channel and control units should all be on different Virtual Channels (VC) when cascaded. The default is the meduim Quality of Service (QoS) zone. Typically, the default medium QoS zone is used. Setting up QoS zones is independant of anything associated with this workbook. The VCs and QoS zones are provided to help channel path planners balance traffic across VCs.
A27: Important Notes
A28: Hidden | B28: Hidden sheets, rows, and columns are not read. Actions are only taken on cells read. Ports on a "Slot x" sheet that do not have a corresponding "Switch_x" sheet are ignored. If the intent is to make changes to the chassis only, then hide all "Switch_x" sheets.
A30: Empty Cell | B30: Rows whose "Area" is empty (cleared) are ignored. An empty parameter indicates that no change should be made to the existing parameter.
A32: Order | B32: Processing begins with the "Chassis" worksheetsheet. “Switch_x” worksheets are only processed when "Configure Switches" is "Yes" on the "Chassis sheet. All items on the chassis sheet are processed in the order they appear, beginning with row 2.
B34: Once “Configure Switches” is encountered on the chassis worksheet, and the value is “Yes”, all switches are created and ports moved to the assigned switch. If a port on any of the “Slot x” worksheets does not have a corresponding “Sheet_x” worksheet, it is left untouched. If a port is found in a logical switch that it doesn’t belong to and there is no corresponding “Switch_x” worksheet, it is moved to the default FID. Since a port must be disabled to move it to another logical switch, F-Ports, ports that are online to a device, are only moved if -force is specified. -force is not required to move E-Ports, switch-to-switch ports. E-Ports are decommissioned, then moved.
B36: “Switch_x" sheets are then processed by row order, same as "Chassis. "Slot x" sheets are only processed when "Configure Ports" is "Yes".
B38: For efficiency, all port actions are processed as a group. “Start Enable” is processed for all ports, followed by “CLI”, then “Reserve”, then “Port Name”, then “End Enable”. If a failure is encountered, each port is then processed one at a time for the action that failed on the group of ports. Keep in mind that a switch cannot be enabled on a disabled chassis and ports cannot be enabled on a disabled switch.
A40: CLI Variables
A41: $cwwn | B41: Replaced with the chassis WWN
A42: $license | B42: Replaced with the WWN used for license generation.
A43: $swwn | B43: Replaced with the the logical switch WWN
A44: $p | B44: Replaced with the port number
A45: $i | B45: Replaced with the port index
A46: $lwwn | B46: Replaced with the login WWN. If there are multiple logins, the command is repeated for each login.

Sheet Slot_x_Terms
A1: Term | B1: Description
A3: Port | B3: DO NOT CHANGE. The port number without the slot indicator. Note that the slot number is determined by the sheet header.
A5: DID (Hex) | B5: The domain ID in hex. This must match the domain ID used on the "Switch_x" sheets for the FID. When using "=" to use the DID on the switch sheet, "0x" and leading "0", if any, must be removed. The example "Slot 0" illustrates how to do this in cell C131. From the bottom up, the remaining ports have been prefilled to match the DID from the previous port.
A7: Port Addr (Hex) | B7: Rarely changed. Should only be changed under the guidance of someone with expert knowledge of FICON link addressing. The intended purpose is for setting non-standard link addresses for mainframe environments. When modifying the link addresses, keep in mind that the mainframe I/O subsystem does not support addresses greater than the maximum number of ports supported by the switch.
A9: Index | B9: DO NOT CHANGE. Since port addresses can change and the port numbering scheme can change based on switch type, the port index gives FOS a consistent way to reference physical ports.
A11: Link Addr | B11: DO NOT CHANGE. The link address is only relevant to mainframe SAN administrators. This field is automatically calculated. The most significant byte is the DID in hex. The least significant byte is the port address.
A13: FID | B13: This is the Fabric ID of the corresponding switch on one of the "Switch_x" sheets. If there is no corresponding FID number on a "Switch_x" sheet, the port is ignored (no changes are made to the port). Similar to DID, but a simple "=" will do. See cell G131 on the "Slot 0" worksheet.
A15: Start Enable | B15: Typically clear (empty cell). Intended to execute CLI commands that require the port to be disabled. By default, all newly added ports are disabled. A disable here only makes sense when reconfiguring existing enabled ports. Although "Enable" and "Persistent Disable" are available options, there is no known practical reason to use them here. Use "End Enable" for final port configuration.
A17: CLI | B17: CLI commands are executed via an SSH session. Use multiple rows with "CLI" in column A or put multiple commands in the same cell on different lines. Commands are executed in the order read. Commands are processed as is. Minimal response evaluation is performed. Typically only used for long distance settings or to lock down a port as E-Port.
B19: Example: Set the long-distance mode on a port to automatically calculate required buffer credits for 100 Km with the default frame size and VC link init 1 using the port number.
B21: portcfglongdistance $p LS 1 -distance 100
B23: Example: Set a port for use as an E-Port only using the port index.
B25: portcfgeport -i $i 2
A27: End Enable | B27: Typically set. The port must be enabled to use it. Disables happen immediately. Enables will not take effect until the port is reserved, the chassis is enabled, and the switch is enabled.
A29: Reserve | B29: Applicable to fixed port switches only. Reserves a POD license for the port. A port cannot be enabled if the license has not been reserved.
A31: Attached Device | B31: This is a comment field only. When using create_swconfig.py, it is pre-filled with RNID data for mainframes or a hash of name server and FDMI information for open systems.
A33: Port Name | B33: Sets the port name. Only used when "Port Name" on the corresponding Switch_x worksheet is "off", "ficon -n", or "open -n". Since no changes to the port name are made if the cell is empty, this means there is no way to clear out old port names using this script.
A35: Low Qos VC, Med Qos VC, and High Qos VC | B35: DO NOT CHANGE. This is the virtual channel that will be used for the port. Not used by switch_config.py. Useful for B/W planning and evaluating ISL congestion.

Sheet Chassis
A1: Area | B1: Parameter | C1: Comments
A3: Enable/Disable | C3: Typically blank (empty cell) which indicates no change. Chassis are only disabled for service actions.
A4: CLI | C4: CLI commands to send via SSH. Typical used to add licenses. See FOS command "license". To modify the management interface IP address, use the FOS command "ipaddrset".
A5: Enable/Disable | C5: Typically blank (empty cell) which indicates no change. If the chassis was disabled to execute CLI commands, then this is typically "Enable". Keep in mind, you can't enable a switch or ports when the chassis is disabled.
A6: Chassis Name | B6: GSH_Chassis | C6: Customer defined user friendly name.
A7: FCR | C7: Fibre Channel Routing (FCR). This is a licensed feature that allows devices in two different SANs to communicate without merging the fabrics. Leave blank for no change.
A8: Message Of The Day | B8: GSH Test Chassis Contact Johnny Fixit West Data Center Aisle 3 Rack A6 | C8: "of the day" is a misnomer. This message is displayed when logging into the chassis via SSH (CLI) regardless of the date. Typically not used. When used, customers usually put site location and service contact information here. Maximum length is 1022 characters. Use a plain text editor so that text with line feeds, <LF>, can be copied and pasted into the cell.
A9: Shell Timeout | B9: 0 | C9: Bash timeout value in seconds. Leave blank for no change. Range: 0-99999. Set to 0 disables bash timeout. FOS default: 0
A10: Session Timeout | B10: 60 | C10: Session timeout value in seconds. Leave blank for no change. Range: 0-99999. Set to 0 disables SSH session timeout. Recommended is 60.
A11: TCP Timeout Level | B11: 5 | C11: Management interface timeout level. Leave blank for no change. Range: 1-5. FOS default and recommended: 5
A12: Max REST Sessions | B12: 3 | C12: Maximum number of REST sessions allowed. FOS default and recommended: 3.
A13: Configure Switches | B13: Yes | C13: Typically "Yes". Chassis processing stops and processing of Switch_x sheets begins.

Sheet Switch_128
A1: Area | B1: Parameter | C1: Comments
A3: Fabric ID (FID) | B3: 128 | C3: Required. FIDs are necessary for FOS to differentiate between logical switches in a chassis. Each logical switch in a chassis must have a unique FID and all logical switches in the same fabric must have the same FID. A FID can be any integer in the range 1 - 128. The recommended best practice is to use FID 128 for the default logical switch. Mainframe: not used in HCD or elsewhere but may appear in error messages.
A4: Enable/Disable | B4: Disable | C4: Typically blank (empty cell) which indicates no change. Newly created logical switches are disabled by default. Switches are usually only disabled for service actions.
A5: Domain ID (DID) | B5: 0x01 | C5: Required unless modifying an existing switch. Empty indicates no change. DID must be in the range 1-0xEF. All switches in a fabric must have a unique DID. Mainframe: The DID is the high byte of the 2-byte address. The recommended best practice is to set the DID to match the Switch ID in HCD.
A6: Insistent DID | B6: Yes | C6: Best practice is "Yes". If the switch type is "ficon", insistent DID will be set regardless of what what is entered here.
A7: CLI | C7: CLI commands to send via SSH. Typically only used for service actions.
A8: Fabric Name | B8: Default_Fab_128 | C8: The recommended best practice is to name fabrics. Mainframe: not used in HCD or elsewhere but may appear in error messages.
A9: Switch Name | B9: Default_Switch_FID_128 | C9: User-friendly switch name. Best practice is to name all logical switches. Mainframe: not used in HCD or elsewhere but may appear in error messages.
A10: Fabric Principal | C10: In fabrics consisting of mixed switch types, it is common to pick the switch on the most resilient and newest chassis. Moot in single switch fabrics or fabrics consisting of all the same switch types.
A11: Fabric Principal Priority | C11: Only relevant if Fabric Principal Enable is "Yes". See FOS CLI fabricprincipal -priority for details. Best practice is 0x0A
A12: Allow XISL | C12: Typically "No". Select "Yes" to share ISLs in a base switch. This should also be "Yes" when creating a base switch.
A13: Login Banner | B13: This is the default switch. There are no active connections. This is a place to hold unused ports. | C13: Same as "Message Of The Day" on the "Chassis" sheet except <LF> is not permitted. This message is displayed when logging into an individual logical switches (setcontext) via the CLI.
A14: Switch Type | B14: open | C14: The default switch can only be "open" or "ficon".
A15: Duplicate WWN | C15: "first-flogi-or-first-fdisc-precedence" (default): The first FLOGI/FDISC are accepted. Subsequent logins for the same WWN are rejected elsewhere in the fabric. Use this for mainframe. Open may use this as well, but that depends on how storage fails-over. "second-flogi-or-secondfdisc-precedence": the second FLOGI/FDISC takes precedence, so the login where the first FLOGI/FDISC for the WWN occured is rejected. This may be used by some storage vendors for automatic fail-over. "first-flogi-or-second-fdisc-precedence": First FLOGI takes precedence but second FDISC takes precedence. This is the most common setting for open systems automatic storage fail-over. This is what allows the storage controller to present WWNs on different ports when there is a port failure. Check with your storage vendor if your not sure.
A16: Bind | C16: Should be "Yes" for mainframe and AIX. Should be "No" for all else. Exceptions are for those with expert knowledge.
A17: Routing Policy | C17: By default, FICON switches are created with DBR. All other switch types use EBR as the default routing policy. For mainframe, FICON, set this to EBR is if FiDR is desired. If "Allow XISL" is "Yes", the routing policy will be that of the base switch regardless of what is entered here.
A18: Port Name | C18: open: No switch wide port naming. Port names may be assigned using the "Slot x" worksheets. Maximum characters: 128. ficon: Same as "open", but characters are limited to 24 characters. index: Default. The port name corresponds to the port index. fdmi: The port name corresponds to the attached FDMI host name. Do not use for FICON. dynamic: The port name corresponds to the format defined by "Port Name Format". For FICON, this field is usually either "ficon" or empty.
A19: Port Name Format | C19: Only applicable if "Port Name" is "dynamic". Search the FOS Admin Guide for "Dynamic Port Name" for an explanation of "dynamic" or the Rest API Guide for "dynamic-portname-format".
A20: Enable/Disable | B20: Enable | C20: Typically "Enable". Typical placed before "Configure Ports" because ports can only be enabled if the switch is enabled.
A21: Enable CUP | C21: FICON only. Must be "Yes" if CUP is defined on any channel connected to this switch.
A22: Configure Ports | B22: Yes | C22: Typically "Yes". Switch_x processing stops and processing of Slot x sheets begins.

Sheet Switch_Open
A1: Area | B1: Parameter | C1: Comments
A3: Fabric ID (FID) | B3: 10 | C3: Required. FIDs are necessary for FOS to differentiate between logical switches in a chassis. Each logical switch in a chassis must have a unique FID and all logical switches in the same fabric must have the same FID. A FID can be any integer in the range 1 - 128. The recommended best practice is to use FID 128 for the default logical switch. Mainframe: not used in HCD or elsewhere but may appear in error messages.
A4: Enable/Disable | C4: Typically blank (empty cell) which indicates no change. Newly created logical switches are disabled by default. Switches are usually only disabled for service actions.
A5: CLI | C5: CLI commands to send via SSH. Typically only used for service actions.
A6: Fabric Name | B6: Open_Fab_10 | C6: The recommended best practice is to name fabrics. Mainframe: not used in HCD or elsewhere but may appear in error messages.
A7: Switch Name | B7: Open_Switch_FID_10 | C7: User-friendly switch name. Best practice is to name all logical switches. Mainframe: not used in HCD or elsewhere but may appear in error messages.
A8: Domain ID (DID) | B8: 0x2D | C8: Required unless modifying an existing switch. Empty indicates no change. DID must be in the range 1-0xEF. All switches in a fabric must have a unique DID. Mainframe: The DID is the high byte of the 2-byte address. The recommended best practice is to set the DID to match the Switch ID in HCD.
A9: Insistent DID | B9: Yes | C9: Best practice is "Yes". Mainframe: If the switch type is "ficon", insistent DID will be set regardless of what what is entered here.
A10: Fabric Principal | B10: Yes | C10: In fabrics consisting of mixed switch types, it is common to pick the switch on the most resilient and newest chassis. Moot in single switch fabrics or fabrics consisting of all the same switch types.
A11: Fabric Principal Priority | B11: 0x0A | C11: Only relevant if Fabric Principal Enable is "Yes". See FOS CLI fabricprincipal -priority for details. Best practice is 0x0A
A12: Allow XISL | B12: Yes | C12: Typically "No". Select "Yes" to share ISLs in a base switch. This should also be "Yes" when creating a base switch.
A13: Login Banner | B13: This is the open switch | C13: Same as "Message Of The Day" on the "Chassis" sheet except <LF> is not permitted. This message is displayed when logging into an individual logical switches (setcontext) via the CLI.
A14: Switch Type | B14: open | C14: Defines the switch type. Mainframe and AIX should always be "ficon".
A15: Duplicate WWN | B15: first-flogi-or-second-fdisc-precedence | C15: "first-flogi-or-first-fdisc-precedence" (default): The first FLOGI/FDISC are accepted. Subsequent logins for the same WWN are rejected elsewhere in the fabric. Use this for mainframe. Open may use this as well, but that depends on how storage fails-over. "second-flogi-or-secondfdisc-precedence": the second FLOGI/FDISC takes precedence, so the login where the first FLOGI/FDISC for the WWN occured is rejected. This may be used by some storage vendors for automatic fail-over. "first-flogi-or-second-fdisc-precedence": First FLOGI takes precedence but second FDISC takes precedence. This is the most common setting for open systems automatic storage failover. This is what allows the storage controller to present WWNs on different ports when there is a port failure. Check with your storage vendor if your not sure.
A16: Bind | B16: No | C16: Should be "Yes" for mainframe and AIX. Should be "No" for all else. Exceptions are for those with expert knowledge.
A17: Routing Policy | B17: EBR | C17: By default, FICON switches are created with DBR. All other switch types use EBR as the default routing policy. For mainframe, FICON, set this to EBR is if FiDR desired.
... A22: Configure Ports | B22: Yes | C22: Typically "Yes". Switch_x processing stops and processing of Slot x sheets begins.

Sheet Switch_FICON
A1: Area | B1: Parameter | C1: Comments
A3: Fabric ID (FID) | B3: 20 | C3: Required. FIDs are necessary for FOS to differentiate between logical switches in a chassis. Each logical switch in a chassis must have a unique FID and all logical switches in the same fabric must have the same FID. A FID can be any integer in the range 1 - 128. The recommended best practice is to use FID 128 for the default logical switch. Mainframe: not used in HCD or elsewhere but may appear in error messages.
A4: Enable/Disable | C4: Typically blank (empty cell) which indicates no change. Newly created logical switches are disabled by default. Switches are usually only disabled for service actions.
A5: CLI | C5: CLI commands to send via SSH. Typically only used for service actions.
A6: Fabric Name | B6: FICON_Fab_20 | C6: The recommended best practice is to name fabrics. Mainframe: not used in HCD or elsewhere but may appear in error messages.
A7: Switch Name | B7: FICON_Switch_FID_20 | C7: User-friendly switch name. Best practice is to name all logical switches. Mainframe: not used in HCD or elsewhere but may appear in error messages.
A8: Domain ID (DID) | B8: 0x2F | C8: Required unless modifying an existing switch. Empty indicates no change. DID must be in the range 1-0xEF. All switches in a fabric must have a unique DID. Mainframe: The DID is the high byte of the 2-byte address. The recommended best practice is to set the DID to match the Switch ID in HCD.
A9: Insistent DID | B9: Yes | C9: Best practice is "Yes". Mainframe: If the switch type is "ficon", insistent DID will be set regardless of what what is entered here.
A10: Fabric Principal | B10: Yes | C10: In fabrics consisting of mixed switch types, it is common to pick the switch on the most resilient and newest chassis. Moot in single switch fabrics or fabrics consisting of all the same switch types.
A11: Fabric Principal Priority | B11: 0x0B | C11: Only relevant if Fabric Principal Enable is "Yes". See FOS CLI fabricprincipal -priority for details. Best practice is 0x0A
A12: Allow XISL | B12: No | C12: Typically "No". Select "Yes" to share ISLs in a base switch. This should also be "Yes" when creating a base switch.
A13: Login Banner | B13: This is the FICON switch | C13: Same as "Message Of The Day" on the "Chassis" sheet except <LF> is not permitted. This message is displayed when logging into an individual logical switches (setcontext) via the CLI.
A14: Switch Type | B14: ficon | C14: Defines the switch type. Mainframe and AIX should always be "ficon".
A15: Duplicate WWN | B15: first-flogi-or-first-fdisc-precedence | C15: "first-flogi-or-first-fdisc-precedence" (default): The first FLOGI/FDISC are accepted. Subsequent logins for the same WWN are rejected elsewhere in the fabric. Use this for mainframe. Open may use this as well, but that depends on how storage fails-over. "second-flogi-or-secondfdisc-precedence": the second FLOGI/FDISC takes precedence, so the login where the first FLOGI/FDISC for the WWN occured is rejected. This may be used by some storage vendors for automatic fail-over. "first-flogi-or-second-fdisc-precedence": First FLOGI takes precedence but second FDISC takes precedence. This is the most common setting for open systems automatic storage failover. This is what allows the storage controller to present WWNs on different ports when there is a port failure. Check with your storage vendor if your not sure.
A16: Bind | B16: Yes | C16: Should be "Yes" for mainframe and AIX. Should be "No" for all else. Exceptions are for those with expert knowledge.
A17: Routing Policy | B17: EBR | C17: By default, FICON switches are created with DBR. All other switch types use EBR as the default routing policy. For mainframe, FICON, set this to EBR is if FiDR is desired. If "Allow XISL" is "Yes", the routing policy will be that of the base switch regardless of what is entered here.
A18: Port Name | B18: ficon | C18: See "Switch_128" for a full explanation.
A19: Port Name Format | C19: Only applicable if "Port Name" is "dynamic". Search the FOS Admin Guide for "Dynamic Port Name" for an explanation of "dynamic" or the Rest API Guide for "dynamic-portname-format".
A20: Enable CUP | B20: No | C20: FICON only. Must be "Yes" if CUP is defined on any channel connected to this switch. A license is required to enable this feature. Most mainframe environments use CUP and therefore set this to "Yes". It is "No" in this example because the test switch I used to validate these examples did not have a FICON license. It has been tested with other switches that did have a CUP license.
A21: Enable/Disable | B21: Enable | C21: Typically "Enable". Port enables are processed after all chassis and switch configuration tasks are complete. Ports will only be enabled if the switch is enabled.
A22: SCC | B22: * | C22: Typically only used for FICON. An SCC policy is required for FICON. For FICON fabrics with multiple switches, cascaded, it is common for SAN administrators to wait until all switches are connected before implementing an SCC policy. Enter * for the WWNs of all switches in the fabric. Use a CSV list to manually add additional WWNs. The existing SCC policy is added to only. For more granualar SCC settings, use scc_policy.py.
A23: FICON Zone | B23: all | C23: FICON only. Ignored if "Switch Type" is not "ficon". Launches mf_zone.py followed by zone_config.py. "all" is the most common zoning method for FICON. Execute "python mf_zone.py -eh" for an explanation of the different zoning options. Use mf_zone.py independantly to zone by channel.
A24: Configure Ports | B24: Yes | C24: Typically "Yes". Switch_x processing stops and processing of Slot x sheets begins.

Sheet Switch_base
A1: Area | B1: Parameter | C1: Comments
A3: Fabric ID (FID) | B3: 30 | C3: Required. FIDs are necessary for FOS to differentiate between logical switches in a chassis. Each logical switch in a chassis must have a unique FID and all logical switches in the same fabric must have the same FID. A FID can be any integer in the range 1 - 128. The recommended best practice is to use FID 128 for the default logical switch. Mainframe: not used in HCD or elsewhere but may appear in error messages.
A4: Enable/Disable | B4: Disable | C4: Typically blank (empty cell) which indicates no change. Newly created logical switches are disabled by default. Switches are usually only disabled for service actions.
A5: CLI | C5: CLI commands to send via SSH. Typically only used for service actions.
A6: Fabric Name | B6: base_Fab_30 | C6: The recommended best practice is to name fabrics. Mainframe: not used in HCD or elsewhere but may appear in error messages.
A7: Switch Name | B7: Base_Switch_FID_30 | C7: User-friendly switch name. Best practice is to name all logical switches. Mainframe: not used in HCD or elsewhere but may appear in error messages.
A8: Domain ID (DID) | B8: 0x01 | C8: Required unless modifying an existing switch. Empty indicates no change. DID must be in the range 1-0xEF. All switches in a fabric must have a unique DID. Mainframe: The DID is the high byte of the 2-byte address. The recommended best practice is to set the DID to match the Switch ID in HCD.
A9: Insistent DID | B9: No | C9: Best practice is "Yes". Mainframe: If the switch type is "ficon", insistent DID will be set regardless of what what is entered here.
A10: Fabric Principal | B10: No | C10: The base switch is essentially a mutliplexer to share ISLs amoung different fabrics. It does not perform many of the fabric functions of other switch types. It does not make sense to set this. Setting this to "Yes" on a base switch may result in an error.
A11: Fabric Principal Priority | C11: Not relevant for a base switch.
A12: Allow XISL | C12: This cell must be empty when creating a base switch.
A13: Login Banner | B13: This is the base switch | C13: Same as "Message Of The Day" on the "Chassis" sheet except <LF> is not permitted. This message is displayed when logging into an individual logical switches (setcontext) via the CLI.
A14: Switch Type | B14: base | C14: Defines the switch type as a base switch.
A15: Duplicate WWN | B15: first-flogi-or-first-fdisc-precedence | C15: This affects how device logins, F-Ports, are handled. Since only E-Ports are allowed in the base switch, this setting is moot. The recommended best practice for a base switch is to set this to set this to "first-flogi-or-first-fdisc-precedence", which is the default for newely created switches.
A16: Bind | B16: No | C16: Should be "No", which is the default for newely created switches. F-Port connections are rejected in the base switch, so port addresses are not relevant.
A17: Routing Policy | B17: EBR | C17: All switches using the base port will use this routing policy regardless of how the routing policy is set for the switches using the base switch, "Allow XSIL" = "Yes". It is rare, if ever, for open environments to use anything other than EBR. Other settings are generally only of concern in mainframe environments where there is a logical switch for mainframe channel connections and a seperate logical switch for peer-to-peer storage connections sharring ISLs. Keep in mind that peer-to-peer storage connection use FCP (open) protocol, not FICON. If you select EBR, make sure all channels and device connections support FiDR.
A18: Port Name | B18: open | C18: See "Switch_128" for a full explanation.
A19: Port Name Format | C19: See "Switch_128" for a full explanation.
A20: Enable CUP | C20: FICON only. Must be "Yes" if the IODF contains any channel with control unit link addresses defined for the E-Ports of the base switch.
A21: Enable/Disable | B21: Enable | C21: Typically "Enable". Keep in mind that ports can only be enabled if the switch is enabled.
A22: Configure Ports | B22: Yes | C22: Typically "Yes". Switch_x processing stops and processing of Slot x sheets begins.

Sheet Slot 0
B1: SLOT 0
B2: Port | C2: DID (Hex) | D2: Port Addr (Hex) | E2: Index | F2: Link Addr | G2: FID | H2: Start Enable | I2: CLI | J2: End Enable | K2: Reserve | L2: Attached Device | M2: Port Name | N2: Low Qos VC | O2: Med Qos VC | P2: High Qos VC
B4: =B5+1 -> 127 | C4: =C5 -> 1 | D4: =DEC2HEX(HEX2DEC(D5)+1) -> 7F | E4: =B4 -> 127 | F4: =IF(HEX2DEC(D4)>15,IF(HEX2DEC(C4) > 15,CONCATENATE(C4,D4),CONCATENATE("0",C4,D4)),IF(HEX2DEC(C4) > 15,CONCATENATE(C4,"0",D4),CONCATENATE("0",C4,"0",D4))) -> 017F | N4: =LOOKUP(HEX2DEC(MID(F4,4,1)),VC!A1:C16) -> 9 | O4: =LOOKUP(HEX2DEC(MID(F4,4,1)),VC!A1:B16) -> 5 | P4: =LOOKUP(HEX2DEC(MID(F4,4,1)),VC!A1:D16) -> 10
B5: =B6+1 -> 126 | C5: =C6 -> 1 | D5: =DEC2HEX(HEX2DEC(D6)+1) -> 7E | E5: =B5 -> 126 | F5: =IF(HEX2DEC(D5)>15,IF(HEX2DEC(C5) > 15,CONCATENATE(C5,D5),CONCATENATE("0",C5,D5)),IF(HEX2DEC(C5) > 15,CONCATENATE(C5,"0",D5),CONCATENATE("0",C5,"0",D5))) -> 017E | N5: =LOOKUP(HEX2DEC(MID(F5,4,1)),VC!A1:C16) -> 8 | O5: =LOOKUP(HEX2DEC(MID(F5,4,1)),VC!A1:B16) -> 4 | P5: =LOOKUP(HEX2DEC(MID(F5,4,1)),VC!A1:D16) -> 14
B6: =B7+1 -> 125 | C6: =C7 -> 1 | D6: =DEC2HEX(HEX2DEC(D7)+1) -> 7D | E6: =B6 -> 125 | F6: =IF(HEX2DEC(D6)>15,IF(HEX2DEC(C6) > 15,CONCATENATE(C6,D6),CONCATENATE("0",C6,D6)),IF(HEX2DEC(C6) > 15,CONCATENATE(C6,"0",D6),CONCATENATE("0",C6,"0",D6))) -> 017D | N6: =LOOKUP(HEX2DEC(MID(F6,4,1)),VC!A1:C16) -> 9 | O6: =LOOKUP(HEX2DEC(MID(F6,4,1)),VC!A1:B16) -> 3 | P6: =LOOKUP(HEX2DEC(MID(F6,4,1)),VC!A1:D16) -> 13
B7: =B8+1 -> 124 | C7: =C8 -> 1 | D7: =DEC2HEX(HEX2DEC(D8)+1) -> 7C | E7: =B7 -> 124 | F7: =IF(HEX2DEC(D7)>15,IF(HEX2DEC(C7) > 15,CONCATENATE(C7,D7),CONCATENATE("0",C7,D7)),IF(HEX2DEC(C7) > 15,CONCATENATE(C7,"0",D7),CONCATENATE("0",C7,"0",D7))) -> 017C | N7: =LOOKUP(HEX2DEC(MID(F7,4,1)),VC!A1:C16) -> 8 | O7: =LOOKUP(HEX2DEC(MID(F7,4,1)),VC!A1:B16) -> 2 | P7: =LOOKUP(HEX2DEC(MID(F7,4,1)),VC!A1:D16) -> 12
B8: =B9+1 -> 123 | C8: =C9 -> 1 | D8: =DEC2HEX(HEX2DEC(D9)+1) -> 7B | E8: =B8 -> 123 | F8: =IF(HEX2DEC(D8)>15,IF(HEX2DEC(C8) > 15,CONCATENATE(C8,D8),CONCATENATE("0",C8,D8)),IF(HEX2DEC(C8) > 15,CONCATENATE(C8,"0",D8),CONCATENATE("0",C8,"0",D8))) -> 017B | N8: =LOOKUP(HEX2DEC(MID(F8,4,1)),VC!A1:C16) -> 9 | O8: =LOOKUP(HEX2DEC(MID(F8,4,1)),VC!A1:B16) -> 5 | P8: =LOOKUP(HEX2DEC(MID(F8,4,1)),VC!A1:D16) -> 11
B9: =B10+1 -> 122 | C9: =C10 -> 1 | D9: =DEC2HEX(HEX2DEC(D10)+1) -> 7A | E9: =B9 -> 122 | F9: =IF(HEX2DEC(D9)>15,IF(HEX2DEC(C9) > 15,CONCATENATE(C9,D9),CONCATENATE("0",C9,D9)),IF(HEX2DEC(C9) > 15,CONCATENATE(C9,"0",D9),CONCATENATE("0",C9,"0",D9))) -> 017A | N9: =LOOKUP(HEX2DEC(MID(F9,4,1)),VC!A1:C16) -> 8 | O9: =LOOKUP(HEX2DEC(MID(F9,4,1)),VC!A1:B16) -> 4 | P9: =LOOKUP(HEX2DEC(MID(F9,4,1)),VC!A1:D16) -> 10
B10: =B11+1 -> 121 | C10: =C11 -> 1 | D10: =DEC2HEX(HEX2DEC(D11)+1) -> 79 | E10: =B10 -> 121 | F10: =IF(HEX2DEC(D10)>15,IF(HEX2DEC(C10) > 15,CONCATENATE(C10,D10),CONCATENATE("0",C10,D10)),IF(HEX2DEC(C10) > 15,CONCATENATE(C10,"0",D10),CONCATENATE("0",C10,"0",D10))) -> 0179 | N10: =LOOKUP(HEX2DEC(MID(F10,4,1)),VC!A1:C16) -> 9 | O10: =LOOKUP(HEX2DEC(MID(F10,4,1)),VC!A1:B16) -> 3 | P10: =LOOKUP(HEX2DEC(MID(F10,4,1)),VC!A1:D16) -> 14
B11: =B12+1 -> 120 | C11: =C12 -> 1 | D11: =DEC2HEX(HEX2DEC(D12)+1) -> 78 | E11: =B11 -> 120 | F11: =IF(HEX2DEC(D11)>15,IF(HEX2DEC(C11) > 15,CONCATENATE(C11,D11),CONCATENATE("0",C11,D11)),IF(HEX2DEC(C11) > 15,CONCATENATE(C11,"0",D11),CONCATENATE("0",C11,"0",D11))) -> 0178 | N11: =LOOKUP(HEX2DEC(MID(F11,4,1)),VC!A1:C16) -> 8 | O11: =LOOKUP(HEX2DEC(MID(F11,4,1)),VC!A1:B16) -> 2 | P11: =LOOKUP(HEX2DEC(MID(F11,4,1)),VC!A1:D16) -> 13
B12: =B13+1 -> 119 | C12: =C13 -> 1 | D12: =DEC2HEX(HEX2DEC(D13)+1) -> 77 | E12: =B12 -> 119 | F12: =IF(HEX2DEC(D12)>15,IF(HEX2DEC(C12) > 15,CONCATENATE(C12,D12),CONCATENATE("0",C12,D12)),IF(HEX2DEC(C12) > 15,CONCATENATE(C12,"0",D12),CONCATENATE("0",C12,"0",D12))) -> 0177 | N12: =LOOKUP(HEX2DEC(MID(F12,4,1)),VC!A1:C16) -> 9 | O12: =LOOKUP(HEX2DEC(MID(F12,4,1)),VC!A1:B16) -> 5 | P12: =LOOKUP(HEX2DEC(MID(F12,4,1)),VC!A1:D16) -> 12
B13: =B14+1 -> 118 | C13: =C14 -> 1 | D13: =DEC2HEX(HEX2DEC(D14)+1) -> 76 | E13: =B13 -> 118 | F13: =IF(HEX2DEC(D13)>15,IF(HEX2DEC(C13) > 15,CONCATENATE(C13,D13),CONCATENATE("0",C13,D13)),IF(HEX2DEC(C13) > 15,CONCATENATE(C13,"0",D13),CONCATENATE("0",C13,"0",D13))) -> 0176 | N13: =LOOKUP(HEX2DEC(MID(F13,4,1)),VC!A1:C16) -> 8 | O13: =LOOKUP(HEX2DEC(MID(F13,4,1)),VC!A1:B16) -> 4 | P13: =LOOKUP(HEX2DEC(MID(F13,4,1)),VC!A1:D16) -> 11
B14: =B15+1 -> 117 | C14: =C15 -> 1 | D14: =DEC2HEX(HEX2DEC(D15)+1) -> 75 | E14: =B14 -> 117 | F14: =IF(HEX2DEC(D14)>15,IF(HEX2DEC(C14) > 15,CONCATENATE(C14,D14),CONCATENATE("0",C14,D14)),IF(HEX2DEC(C14) > 15,CONCATENATE(C14,"0",D14),CONCATENATE("0",C14,"0",D14))) -> 0175 | N14: =LOOKUP(HEX2DEC(MID(F14,4,1)),VC!A1:C16) -> 9 | O14: =LOOKUP(HEX2DEC(MID(F14,4,1)),VC!A1:B16) -> 3 | P14: =LOOKUP(HEX2DEC(MID(F14,4,1)),VC!A1:D16) -> 10
B15: =B16+1 -> 116 | C15: =C16 -> 1 | D15: =DEC2HEX(HEX2DEC(D16)+1) -> 74 | E15: =B15 -> 116 | F15: =IF(HEX2DEC(D15)>15,IF(HEX2DEC(C15) > 15,CONCATENATE(C15,D15),CONCATENATE("0",C15,D15)),IF(HEX2DEC(C15) > 15,CONCATENATE(C15,"0",D15),CONCATENATE("0",C15,"0",D15))) -> 0174 | N15: =LOOKUP(HEX2DEC(MID(F15,4,1)),VC!A1:C16) -> 8 | O15: =LOOKUP(HEX2DEC(MID(F15,4,1)),VC!A1:B16) -> 2 | P15: =LOOKUP(HEX2DEC(MID(F15,4,1)),VC!A1:D16) -> 14
B16: =B17+1 -> 115 | C16: =C17 -> 1 | D16: =DEC2HEX(HEX2DEC(D17)+1) -> 73 | E16: =B16 -> 115 | F16: =IF(HEX2DEC(D16)>15,IF(HEX2DEC(C16) > 15,CONCATENATE(C16,D16),CONCATENATE("0",C16,D16)),IF(HEX2DEC(C16) > 15,CONCATENATE(C16,"0",D16),CONCATENATE("0",C16,"0",D16))) -> 0173 | N16: =LOOKUP(HEX2DEC(MID(F16,4,1)),VC!A1:C16) -> 9 | O16: =LOOKUP(HEX2DEC(MID(F16,4,1)),VC!A1:B16) -> 5 | P16: =LOOKUP(HEX2DEC(MID(F16,4,1)),VC!A1:D16) -> 13
B17: =B18+1 -> 114 | C17: =C18 -> 1 | D17: =DEC2HEX(HEX2DEC(D18)+1) -> 72 | E17: =B17 -> 114 | F17: =IF(HEX2DEC(D17)>15,IF(HEX2DEC(C17) > 15,CONCATENATE(C17,D17),CONCATENATE("0",C17,D17)),IF(HEX2DEC(C17) > 15,CONCATENATE(C17,"0",D17),CONCATENATE("0",C17,"0",D17))) -> 0172 | N17: =LOOKUP(HEX2DEC(MID(F17,4,1)),VC!A1:C16) -> 8 | O17: =LOOKUP(HEX2DEC(MID(F17,4,1)),VC!A1:B16) -> 4 | P17: =LOOKUP(HEX2DEC(MID(F17,4,1)),VC!A1:D16) -> 12
B18: =B19+1 -> 113 | C18: =C19 -> 1 | D18: =DEC2HEX(HEX2DEC(D19)+1) -> 71 | E18: =B18 -> 113 | F18: =IF(HEX2DEC(D18)>15,IF(HEX2DEC(C18) > 15,CONCATENATE(C18,D18),CONCATENATE("0",C18,D18)),IF(HEX2DEC(C18) > 15,CONCATENATE(C18,"0",D18),CONCATENATE("0",C18,"0",D18))) -> 0171 | N18: =LOOKUP(HEX2DEC(MID(F18,4,1)),VC!A1:C16) -> 9 | O18: =LOOKUP(HEX2DEC(MID(F18,4,1)),VC!A1:B16) -> 3 | P18: =LOOKUP(HEX2DEC(MID(F18,4,1)),VC!A1:D16) -> 11
B19: =B20+1 -> 112 | C19: =C20 -> 1 | D19: =DEC2HEX(HEX2DEC(D20)+1) -> 70 | E19: =B19 -> 112 | F19: =IF(HEX2DEC(D19)>15,IF(HEX2DEC(C19) > 15,CONCATENATE(C19,D19),CONCATENATE("0",C19,D19)),IF(HEX2DEC(C19) > 15,CONCATENATE(C19,"0",D19),CONCATENATE("0",C19,"0",D19))) -> 0170 | N19: =LOOKUP(HEX2DEC(MID(F19,4,1)),VC!A1:C16) -> 8 | O19: =LOOKUP(HEX2DEC(MID(F19,4,1)),VC!A1:B16) -> 2 | P19: =LOOKUP(HEX2DEC(MID(F19,4,1)),VC!A1:D16) -> 10
B20: =B21+1 -> 111 | C20: =C21 -> 1 | D20: =DEC2HEX(HEX2DEC(D21)+1) -> 6F | E20: =B20 -> 111 | F20: =IF(HEX2DEC(D20)>15,IF(HEX2DEC(C20) > 15,CONCATENATE(C20,D20),CONCATENATE("0",C20,D20)),IF(HEX2DEC(C20) > 15,CONCATENATE(C20,"0",D20),CONCATENATE("0",C20,"0",D20))) -> 016F | N20: =LOOKUP(HEX2DEC(MID(F20,4,1)),VC!A1:C16) -> 9 | O20: =LOOKUP(HEX2DEC(MID(F20,4,1)),VC!A1:B16) -> 5 | P20: =LOOKUP(HEX2DEC(MID(F20,4,1)),VC!A1:D16) -> 10
B21: =B22+1 -> 110 | C21: =C22 -> 1 | D21: =DEC2HEX(HEX2DEC(D22)+1) -> 6E | E21: =B21 -> 110 | F21: =IF(HEX2DEC(D21)>15,IF(HEX2DEC(C21) > 15,CONCATENATE(C21,D21),CONCATENATE("0",C21,D21)),IF(HEX2DEC(C21) > 15,CONCATENATE(C21,"0",D21),CONCATENATE("0",C21,"0",D21))) -> 016E | N21: =LOOKUP(HEX2DEC(MID(F21,4,1)),VC!A1:C16) -> 8 | O21: =LOOKUP(HEX2DEC(MID(F21,4,1)),VC!A1:B16) -> 4 | P21: =LOOKUP(HEX2DEC(MID(F21,4,1)),VC!A1:D16) -> 14
B22: =B23+1 -> 109 | C22: =C23 -> 1 | D22: =DEC2HEX(HEX2DEC(D23)+1) -> 6D | E22: =B22 -> 109 | F22: =IF(HEX2DEC(D22)>15,IF(HEX2DEC(C22) > 15,CONCATENATE(C22,D22),CONCATENATE("0",C22,D22)),IF(HEX2DEC(C22) > 15,CONCATENATE(C22,"0",D22),CONCATENATE("0",C22,"0",D22))) -> 016D | N22: =LOOKUP(HEX2DEC(MID(F22,4,1)),VC!A1:C16) -> 9 | O22: =LOOKUP(HEX2DEC(MID(F22,4,1)),VC!A1:B16) -> 3 | P22: =LOOKUP(HEX2DEC(MID(F22,4,1)),VC!A1:D16) -> 13
B23: =B24+1 -> 108 | C23: =C24 -> 1 | D23: =DEC2HEX(HEX2DEC(D24)+1) -> 6C | E23: =B23 -> 108 | F23: =IF(HEX2DEC(D23)>15,IF(HEX2DEC(C23) > 15,CONCATENATE(C23,D23),CONCATENATE("0",C23,D23)),IF(HEX2DEC(C23) > 15,CONCATENATE(C23,"0",D23),CONCATENATE("0",C23,"0",D23))) -> 016C | N23: =LOOKUP(HEX2DEC(MID(F23,4,1)),VC!A1:C16) -> 8 | O23: =LOOKUP(HEX2DEC(MID(F23,4,1)),VC!A1:B16) -> 2 | P23: =LOOKUP(HEX2DEC(MID(F23,4,1)),VC!A1:D16) -> 12
B24: =B25+1 -> 107 | C24: =C25 -> 1 | D24: =DEC2HEX(HEX2DEC(D25)+1) -> 6B | E24: =B24 -> 107 | F24: =IF(HEX2DEC(D24)>15,IF(HEX2DEC(C24) > 15,CONCATENATE(C24,D24),CONCATENATE("0",C24,D24)),IF(HEX2DEC(C24) > 15,CONCATENATE(C24,"0",D24),CONCATENATE("0",C24,"0",D24))) -> 016B | N24: =LOOKUP(HEX2DEC(MID(F24,4,1)),VC!A1:C16) -> 9 | O24: =LOOKUP(HEX2DEC(MID(F24,4,1)),VC!A1:B16) -> 5 | P24: =LOOKUP(HEX2DEC(MID(F24,4,1)),VC!A1:D16) -> 11
B25: =B26+1 -> 106 | C25: =C26 -> 1 | D25: =DEC2HEX(HEX2DEC(D26)+1) -> 6A | E25: =B25 -> 106 | F25: =IF(HEX2DEC(D25)>15,IF(HEX2DEC(C25) > 15,CONCATENATE(C25,D25),CONCATENATE("0",C25,D25)),IF(HEX2DEC(C25) > 15,CONCATENATE(C25,"0",D25),CONCATENATE("0",C25,"0",D25))) -> 016A | N25: =LOOKUP(HEX2DEC(MID(F25,4,1)),VC!A1:C16) -> 8 | O25: =LOOKUP(HEX2DEC(MID(F25,4,1)),VC!A1:B16) -> 4 | P25: =LOOKUP(HEX2DEC(MID(F25,4,1)),VC!A1:D16) -> 10
B26: =B27+1 -> 105 | C26: =C27 -> 1 | D26: =DEC2HEX(HEX2DEC(D27)+1) -> 69 | E26: =B26 -> 105 | F26: =IF(HEX2DEC(D26)>15,IF(HEX2DEC(C26) > 15,CONCATENATE(C26,D26),CONCATENATE("0",C26,D26)),IF(HEX2DEC(C26) > 15,CONCATENATE(C26,"0",D26),CONCATENATE("0",C26,"0",D26))) -> 0169 | N26: =LOOKUP(HEX2DEC(MID(F26,4,1)),VC!A1:C16) -> 9 | O26: =LOOKUP(HEX2DEC(MID(F26,4,1)),VC!A1:B16) -> 3 | P26: =LOOKUP(HEX2DEC(MID(F26,4,1)),VC!A1:D16) -> 14
B27: =B28+1 -> 104 | C27: =C28 -> 1 | D27: =DEC2HEX(HEX2DEC(D28)+1) -> 68 | E27: =B27 -> 104 | F27: =IF(HEX2DEC(D27)>15,IF(HEX2DEC(C27) > 15,CONCATENATE(C27,D27),CONCATENATE("0",C27,D27)),IF(HEX2DEC(C27) > 15,CONCATENATE(C27,"0",D27),CONCATENATE("0",C27,"0",D27))) -> 0168 | N27: =LOOKUP(HEX2DEC(MID(F27,4,1)),VC!A1:C16) -> 8 | O27: =LOOKUP(HEX2DEC(MID(F27,4,1)),VC!A1:B16) -> 2 | P27: =LOOKUP(HEX2DEC(MID(F27,4,1)),VC!A1:D16) -> 13
B28: =B29+1 -> 103 | C28: =C29 -> 1 | D28: =DEC2HEX(HEX2DEC(D29)+1) -> 67 | E28: =B28 -> 103 | F28: =IF(HEX2DEC(D28)>15,IF(HEX2DEC(C28) > 15,CONCATENATE(C28,D28),CONCATENATE("0",C28,D28)),IF(HEX2DEC(C28) > 15,CONCATENATE(C28,"0",D28),CONCATENATE("0",C28,"0",D28))) -> 0167 | N28: =LOOKUP(HEX2DEC(MID(F28,4,1)),VC!A1:C16) -> 9 | O28: =LOOKUP(HEX2DEC(MID(F28,4,1)),VC!A1:B16) -> 5 | P28: =LOOKUP(HEX2DEC(MID(F28,4,1)),VC!A1:D16) -> 12
B29: =B30+1 -> 102 | C29: =C30 -> 1 | D29: =DEC2HEX(HEX2DEC(D30)+1) -> 66 | E29: =B29 -> 102 | F29: =IF(HEX2DEC(D29)>15,IF(HEX2DEC(C29) > 15,CONCATENATE(C29,D29),CONCATENATE("0",C29,D29)),IF(HEX2DEC(C29) > 15,CONCATENATE(C29,"0",D29),CONCATENATE("0",C29,"0",D29))) -> 0166 | N29: =LOOKUP(HEX2DEC(MID(F29,4,1)),VC!A1:C16) -> 8 | O29: =LOOKUP(HEX2DEC(MID(F29,4,1)),VC!A1:B16) -> 4 | P29: =LOOKUP(HEX2DEC(MID(F29,4,1)),VC!A1:D16) -> 11
B30: =B31+1 -> 101 | C30: =C31 -> 1 | D30: =DEC2HEX(HEX2DEC(D31)+1) -> 65 | E30: =B30 -> 101 | F30: =IF(HEX2DEC(D30)>15,IF(HEX2DEC(C30) > 15,CONCATENATE(C30,D30),CONCATENATE("0",C30,D30)),IF(HEX2DEC(C30) > 15,CONCATENATE(C30,"0",D30),CONCATENATE("0",C30,"0",D30))) -> 0165 | N30: =LOOKUP(HEX2DEC(MID(F30,4,1)),VC!A1:C16) -> 9 | O30: =LOOKUP(HEX2DEC(MID(F30,4,1)),VC!A1:B16) -> 3 | P30: =LOOKUP(HEX2DEC(MID(F30,4,1)),VC!A1:D16) -> 10
B31: =B32+1 -> 100 | C31: =C32 -> 1 | D31: =DEC2HEX(HEX2DEC(D32)+1) -> 64 | E31: =B31 -> 100 | F31: =IF(HEX2DEC(D31)>15,IF(HEX2DEC(C31) > 15,CONCATENATE(C31,D31),CONCATENATE("0",C31,D31)),IF(HEX2DEC(C31) > 15,CONCATENATE(C31,"0",D31),CONCATENATE("0",C31,"0",D31))) -> 0164 | N31: =LOOKUP(HEX2DEC(MID(F31,4,1)),VC!A1:C16) -> 8 | O31: =LOOKUP(HEX2DEC(MID(F31,4,1)),VC!A1:B16) -> 2 | P31: =LOOKUP(HEX2DEC(MID(F31,4,1)),VC!A1:D16) -> 14
B32: =B33+1 -> 99 | C32: =C33 -> 1 | D32: =DEC2HEX(HEX2DEC(D33)+1) -> 63 | E32: =B32 -> 99 | F32: =IF(HEX2DEC(D32)>15,IF(HEX2DEC(C32) > 15,CONCATENATE(C32,D32),CONCATENATE("0",C32,D32)),IF(HEX2DEC(C32) > 15,CONCATENATE(C32,"0",D32),CONCATENATE("0",C32,"0",D32))) -> 0163 | N32: =LOOKUP(HEX2DEC(MID(F32,4,1)),VC!A1:C16) -> 9 | O32: =LOOKUP(HEX2DEC(MID(F32,4,1)),VC!A1:B16) -> 5 | P32: =LOOKUP(HEX2DEC(MID(F32,4,1)),VC!A1:D16) -> 13
B33: =B34+1 -> 98 | C33: =C34 -> 1 | D33: =DEC2HEX(HEX2DEC(D34)+1) -> 62 | E33: =B33 -> 98 | F33: =IF(HEX2DEC(D33)>15,IF(HEX2DEC(C33) > 15,CONCATENATE(C33,D33),CONCATENATE("0",C33,D33)),IF(HEX2DEC(C33) > 15,CONCATENATE(C33,"0",D33),CONCATENATE("0",C33,"0",D33))) -> 0162 | N33: =LOOKUP(HEX2DEC(MID(F33,4,1)),VC!A1:C16) -> 8 | O33: =LOOKUP(HEX2DEC(MID(F33,4,1)),VC!A1:B16) -> 4 | P33: =LOOKUP(HEX2DEC(MID(F33,4,1)),VC!A1:D16) -> 12
B34: =B35+1 -> 97 | C34: =C35 -> 1 | D34: =DEC2HEX(HEX2DEC(D35)+1) -> 61 | E34: =B34 -> 97 | F34: =IF(HEX2DEC(D34)>15,IF(HEX2DEC(C34) > 15,CONCATENATE(C34,D34),CONCATENATE("0",C34,D34)),IF(HEX2DEC(C34) > 15,CONCATENATE(C34,"0",D34),CONCATENATE("0",C34,"0",D34))) -> 0161 | N34: =LOOKUP(HEX2DEC(MID(F34,4,1)),VC!A1:C16) -> 9 | O34: =LOOKUP(HEX2DEC(MID(F34,4,1)),VC!A1:B16) -> 3 | P34: =LOOKUP(HEX2DEC(MID(F34,4,1)),VC!A1:D16) -> 11
B35: =B36+1 -> 96 | C35: =C36 -> 1 | D35: =DEC2HEX(HEX2DEC(D36)+1) -> 60 | E35: =B35 -> 96 | F35: =IF(HEX2DEC(D35)>15,IF(HEX2DEC(C35) > 15,CONCATENATE(C35,D35),CONCATENATE("0",C35,D35)),IF(HEX2DEC(C35) > 15,CONCATENATE(C35,"0",D35),CONCATENATE("0",C35,"0",D35))) -> 0160 | N35: =LOOKUP(HEX2DEC(MID(F35,4,1)),VC!A1:C16) -> 8 | O35: =LOOKUP(HEX2DEC(MID(F35,4,1)),VC!A1:B16) -> 2 | P35: =LOOKUP(HEX2DEC(MID(F35,4,1)),VC!A1:D16) -> 10
B36: =B37+1 -> 95 | C36: =C37 -> 1 | D36: =DEC2HEX(HEX2DEC(D37)+1) -> 5F | E36: =B36 -> 95 | F36: =IF(HEX2DEC(D36)>15,IF(HEX2DEC(C36) > 15,CONCATENATE(C36,D36),CONCATENATE("0",C36,D36)),IF(HEX2DEC(C36) > 15,CONCATENATE(C36,"0",D36),CONCATENATE("0",C36,"0",D36))) -> 015F | N36: =LOOKUP(HEX2DEC(MID(F36,4,1)),VC!A1:C16) -> 9 | O36: =LOOKUP(HEX2DEC(MID(F36,4,1)),VC!A1:B16) -> 5 | P36: =LOOKUP(HEX2DEC(MID(F36,4,1)),VC!A1:D16) -> 10
B37: =B38+1 -> 94 | C37: =C38 -> 1 | D37: =DEC2HEX(HEX2DEC(D38)+1) -> 5E | E37: =B37 -> 94 | F37: =IF(HEX2DEC(D37)>15,IF(HEX2DEC(C37) > 15,CONCATENATE(C37,D37),CONCATENATE("0",C37,D37)),IF(HEX2DEC(C37) > 15,CONCATENATE(C37,"0",D37),CONCATENATE("0",C37,"0",D37))) -> 015E | N37: =LOOKUP(HEX2DEC(MID(F37,4,1)),VC!A1:C16) -> 8 | O37: =LOOKUP(HEX2DEC(MID(F37,4,1)),VC!A1:B16) -> 4 | P37: =LOOKUP(HEX2DEC(MID(F37,4,1)),VC!A1:D16) -> 14
B38: =B39+1 -> 93 | C38: =C39 -> 1 | D38: =DEC2HEX(HEX2DEC(D39)+1) -> 5D | E38: =B38 -> 93 | F38: =IF(HEX2DEC(D38)>15,IF(HEX2DEC(C38) > 15,CONCATENATE(C38,D38),CONCATENATE("0",C38,D38)),IF(HEX2DEC(C38) > 15,CONCATENATE(C38,"0",D38),CONCATENATE("0",C38,"0",D38))) -> 015D | N38: =LOOKUP(HEX2DEC(MID(F38,4,1)),VC!A1:C16) -> 9 | O38: =LOOKUP(HEX2DEC(MID(F38,4,1)),VC!A1:B16) -> 3 | P38: =LOOKUP(HEX2DEC(MID(F38,4,1)),VC!A1:D16) -> 13
B39: =B40+1 -> 92 | C39: =C40 -> 1 | D39: =DEC2HEX(HEX2DEC(D40)+1) -> 5C | E39: =B39 -> 92 | F39: =IF(HEX2DEC(D39)>15,IF(HEX2DEC(C39) > 15,CONCATENATE(C39,D39),CONCATENATE("0",C39,D39)),IF(HEX2DEC(C39) > 15,CONCATENATE(C39,"0",D39),CONCATENATE("0",C39,"0",D39))) -> 015C | N39: =LOOKUP(HEX2DEC(MID(F39,4,1)),VC!A1:C16) -> 8 | O39: =LOOKUP(HEX2DEC(MID(F39,4,1)),VC!A1:B16) -> 2 | P39: =LOOKUP(HEX2DEC(MID(F39,4,1)),VC!A1:D16) -> 12
B40: =B41+1 -> 91 | C40: =C41 -> 1 | D40: =DEC2HEX(HEX2DEC(D41)+1) -> 5B | E40: =B40 -> 91 | F40: =IF(HEX2DEC(D40)>15,IF(HEX2DEC(C40) > 15,CONCATENATE(C40,D40),CONCATENATE("0",C40,D40)),IF(HEX2DEC(C40) > 15,CONCATENATE(C40,"0",D40),CONCATENATE("0",C40,"0",D40))) -> 015B | N40: =LOOKUP(HEX2DEC(MID(F40,4,1)),VC!A1:C16) -> 9 | O40: =LOOKUP(HEX2DEC(MID(F40,4,1)),VC!A1:B16) -> 5 | P40: =LOOKUP(HEX2DEC(MID(F40,4,1)),VC!A1:D16) -> 11
B41: =B42+1 -> 90 | C41: =C42 -> 1 | D41: =DEC2HEX(HEX2DEC(D42)+1) -> 5A | E41: =B41 -> 90 | F41: =IF(HEX2DEC(D41)>15,IF(HEX2DEC(C41) > 15,CONCATENATE(C41,D41),CONCATENATE("0",C41,D41)),IF(HEX2DEC(C41) > 15,CONCATENATE(C41,"0",D41),CONCATENATE("0",C41,"0",D41))) -> 015A | N41: =LOOKUP(HEX2DEC(MID(F41,4,1)),VC!A1:C16) -> 8 | O41: =LOOKUP(HEX2DEC(MID(F41,4,1)),VC!A1:B16) -> 4 | P41: =LOOKUP(HEX2DEC(MID(F41,4,1)),VC!A1:D16) -> 10
...

Sheet lists
A1: DID | B1: FID | C1: Type | D1: Fab Principal | E1: aptpolicy
A2: 0x01 | B2: 1 | C2: base | D2: 0x01 | E2: PBR
A3: 0x02 | B3: =B2+1 -> 2 | C3: ficon | D3: 0x02 | E3: DBR
A4: 0x03 | B4: =B3+1 -> 3 | C4: open | D4: 0x03 | E4: EBR
A5: 0x04 | B5: =B4+1 -> 4 | D5: 0x04
A6: 0x05 | B6: =B5+1 -> 5 | D6: 0x05
A7: 0x06 | B7: =B6+1 -> 6 | D7: 0x06
A8: 0x07 | B8: =B7+1 -> 7 | D8: 0x07
A9: 0x08 | B9: =B8+1 -> 8 | D9: 0x08
A10: 0x09 | B10: =B9+1 -> 9 | D10: 0x09
A11: 0x0A | B11: =B10+1 -> 10 | D11: 0x0A
A12: 0x0B | B12: =B11+1 -> 11 | D12: 0x0B
A13: 0x0C | B13: =B12+1 -> 12 | D13: 0x0C
A14: 0x0D | B14: =B13+1 -> 13 | D14: 0x0D
A15: 0x0E | B15: =B14+1 -> 14 | D15: 0x0E
A16: 0x0F | B16: =B15+1 -> 15 | D16: 0x0F
... A129: 0x80 | B129: =B128+1 -> 128 | D129: 0x80
A130: 0x81 | D130: 0x81
A131: 0x82 | D131: 0x82
A132: 0x83 | D132: 0x83
A133: 0x84 | D133: 0x84
A134: 0x85 | D134: 0x85
A135: 0x86 | D135: 0x86
A136: 0x87 | D136: 0x87
A137: 0x88 | D137: 0x88
A138: 0x89 | D138: 0x89
A139: 0x8A | D139: 0x8A
A140: 0x8B | D140: 0x8B
A141: 0x8C | D141: 0x8C
... A240: 0xEF | D240: 0xEF
D241: 0xF0
D242: 0xF1
D243: 0xF2
D244: 0xF3
D245: 0xF4
D246: 0xF5
D247: 0xF6
D248: 0xF7
D249: 0xF8
D250: 0xF9
...

Sheet VC
A1: 0 | B1: 2 | C1: 8 | D1: 10
A2: 1 | B2: 3 | C2: 9 | D2: 11
A3: 2 | B3: 4 | C3: 8 | D3: 12
A4: 3 | B4: 5 | C4: 9 | D4: 13
A5: 4 | B5: 2 | C5: 8 | D5: 14
A6: 5 | B6: 3 | C6: 9 | D6: 10
A7: 6 | B7: 4 | C7: 8 | D7: 11
A8: 7 | B8: 5 | C8: 9 | D8: 12
A9: 8 | B9: 2 | C9: 8 | D9: 13
A10: 9 | B10: 3 | C10: 9 | D10: 14
A11: 10 | B11: 4 | C11: 8 | D11: 10
A12: 11 | B12: 5 | C12: 9 | D12: 11
... A16: 15 | B16: 5 | C16: 9 | D16: 10
B18: Med | C18: Low | D18: High
