Workbook

Sheet Instructions
A1: Intended for use with switch_config.py. See "switch_config_example.xlsx".
A3: Step 1
A4: Make a copy of this workbook
A6: Step 2
A7: Define the chassis parameters on the "Chassis" sheet.
A9: Step 3
A10: Define the switch(es) using the "Switch_x" sheet. Make copies of this sheet to define multiple switches. All sheet names beginning with "Switch_" are assumed to be a switch configuration worksheet. The "x" in tab name is only used so that Excel has unique sheet names. Typically, x is replaced with the FID number or user-friendly switch name, but it is not used by scripts that read this workbook. It can be whatever you want. Keep in mind that most of the switch configuration items require the switch to be disabled. When switches are newly created, they are disabled.
A12: Step 4
A13: Fill out the "Slot 0" Worksheet. See the "Slot_x_Terms" tab for details. Only ports with a FID that matches a FID on a “Switch_x” worksheet are acted on. All other ports are ignored.
A15: Command Line Options
A16: -force | B16: Disables are only performed when -force is specified. Keep in mind the CLI is not interpreted. Although not recommended, you can disabled something with a CLI command.
A18: -cli | B18: CLI is only executed if -cli is specified. CLI is always executed when -cli is specified. CLI commands are executed as is. There is no ability to respond to interactive CLI commands. For error reporting purposes, some basic parsing of CLI responses are performed, but administrators should be aware that several error conditions are not processed. This means you can do whatever you want with CLI commands. Just keep in mind that just because you can do whatever you want, that doesn't mean you want to do whatever you can do.
A21: Best Effort
A22: A best effort algorithm is applied. Errors are reported as they are encountered, but processing continues.
A24: FICON Tip
A25: When possible, the channel and control units should all be on different Virtual Channels (VC) when cascaded. The default is the meduim Quality of Service (QoS) zone. Typically, the default medium QoS zone is used. Setting up QoS zones is independant of anything associated with this workbook. The VCs and QoS zones are provided to help channel path planners balance traffic across VCs.
A27: Important Notes
A28: Hidden | B28: Hidden sheets, rows, and columns are not read. Actions are only taken on cells read. Ports on a "Slot x" sheet that do not have a corresponding "Switch_x" sheet are ignored. If the intent is to make changes to the chassis only, then hide all "Switch_x" sheets.
A30: Empty Cell | B30: Rows whose "Area" is empty (cleared) are ignored. An empty parameter indicates that no change should be made to the existing parameter.
A32: Order | B32: Processing begins with the "Chassis" worksheetsheet. “Switch_x” worksheets are only processed when "Configure Switches" is "Yes" on the "Chassis sheet. All items on the chassis sheet are processed in the order they appear, beginning with row 2.
B34: Once “Configure Switches” is encountered on the chassis worksheet, and the value is “Yes”, all switches are created and ports moved to the assigned switch. If a port on any of the “Slot x” worksheets does not have a corresponding “Sheet_x” worksheet, it is left untouched. If a port is found in a logical switch that it doesn’t belong to and there is no corresponding “Switch_x” worksheet, it is moved to the default FID. Since a port must be disabled to move it to another logical switch, F-Ports, ports that are online to a device, are only moved if -force is specified. -force is not required to move E-Ports, switch-to-switch ports. E-Ports are decommissioned, then moved.
B36: “Switch_x" sheets are then processed by row order, same as "Chassis. "Slot x" sheets are only processed when "Configure Ports" is "Yes".
B38: For efficiency, all port actions are processed as a group. “Start Enable” is processed for all ports, followed by “CLI”, then “Reserve”, then “Port Name”, then “End Enable”. If a failure is encountered, each port is then processed one at a time for the action that failed on the group of ports. Keep in mind that a switch cannot be enabled on a disabled chassis and ports cannot be enabled on a disabled switch.
A40: CLI Variables
A41: $cwwn | B41: Replaced with the chassis WWN
A42: $license | B42: Replaced with the WWN used for license generation.
A43: $swwn | B43: Replaced with the the logical switch WWN
A44: $p | B44: Replaced with the port number
A45: $i | B45: Replaced with the port index
A46: $lwwn | B46: Replaced with the login WWN. If there are multiple logins, the command is repeated for each login.

Sheet Slot_x_Terms
A1: Term | B1: Description
A3: Port | B3: DO NOT CHANGE. The port number without the slot indicator. Note that the slot number is determined by the sheet header.
A5: DID (Hex) | B5: The domain ID in hex. This must match the domain ID used on the "Switch_x" sheets for the FID. When using "=" to use the DID on the switch sheet, "0x" and leading "0", if any, must be removed. The example "Slot 0" illustrates how to do this in cell C131. From the bottom up, the remaining ports have been prefilled to match the DID from the previous port.
A7: Port Addr (Hex) | B7: Rarely changed. Should only be changed under the guidance of someone with expert knowledge of FICON link addressing. The intended purpose is for setting non-standard link addresses for mainframe environments. When modifying the link addresses, keep in mind that the mainframe I/O subsystem does not support addresses greater than the maximum number of ports supported by the switch.
A9: Index | B9: DO NOT CHANGE. Since port addresses can change and the port numbering scheme can change based on switch type, the port index gives FOS a consistent way to reference physical ports.
A11: Link Addr | B11: DO NOT CHANGE. The link address is only relevant to mainframe SAN administrators. This field is automatically calculated. The most significant byte is the DID in hex. The least significant byte is the port address.
A13: FID | B13: This is the Fabric ID of the corresponding switch on one of the "Switch_x" sheets. If there is no corresponding FID number on a "Switch_x" sheet, the port is ignored (no changes are made to the port). Similar to DID, but a simple "=" will do. See cell G131 on the "Slot 0" worksheet.
A15: Start Enable | B15: Typically clear (empty cell). Usually only used for service actions. "Disable" is only executed with -force. By default, all newly added ports are disabled. When "Disable" or "Persistent Disable" is selected, that is the first action executed. "Enable" is only valid if the switch is enabled.
A17: CLI | B17: CLI commands are executed via an SSH session. Use multiple rows with "CLI" in column A or put multiple commands in the same cell on different lines. Commands are executed in the order read. Commands are processed as is. Minimal response evaluation is performed. Typically only used for long distance settings or to lock down a port as E-Port.
B19: Example: Set the long-distance mode on a port to automatically calculate required buffer credits for 100 Km with the default frame size and VC link init 1 using the port number.
B21: portcfglongdistance $p LS 1 -distance 100
B23: Example: Set a port for use as an E-Port only using the port index.
B25: portcfgeport -i $i 2
A27: End Enable | B27: Typically "Enable". Executed after all other actions are completed.
A29: Reserve | B29: Typically "Yes". Applicable to fixed port switches only. Reserves a port license for the port.
A31: Attached Device | B31: This is a comment field only. When using create_swconfig.py, it is pre-filled with RNID data for mainframes or a hash of name server and FDMI information for open systems.
A33: Port Name | B33: Sets the port name. Only used when "Port Name" on the corresponding Switch_x worksheet is "off", "ficon -n", or "open -n". Since no changes to the port name are made if the cell is empty, this means there is no way to clear out old port names using this script.
A35: Low Qos VC, Med Qos VC, and High Qos VC | B35: DO NOT CHANGE. This is the virtual channel that will be used for the port. Not used by switch_config.py. Useful for B/W planning and evaluating ISL congestion.

Sheet Chassis
A1: Area | B1: Parameter | C1: Comments
A3: Enable/Disable | C3: Typically blank (empty cell) which indicates no change. Chassis are only disabled for service actions.
A4: CLI | C4: CLI commands to send via SSH. Typical used to add licenses. See FOS command "license". To modify the management interface IP address, use the FOS command "ipaddrset".
A5: Enable/Disable | C5: Typically blank (empty cell) which indicates no change. If the chassis was disabled to execute CLI commands, then this is typically "Enable". Keep in mind, you can't enable a switch or ports when the chassis is disabled.
A6: Chassis Name | B6: GSH_Chassis | C6: Customer defined user friendly name.
A7: FCR | C7: Fibre Channel Routing (FCR). This is a licensed feature that allows devices in two different SANs to communicate without merging the fabrics. Leave blank for no change.
A8: Message Of The Day | C8: "of the day" is a misnomer. This message is displayed when logging into the chassis via SSH (CLI) regardless of the date. Typically not used. When used, customers usually put site location and service contact information here. Maximum length is 1022 characters. Use a plain text editor so that formatted text can be copied and pasted into the cell.
A9: Shell Timeout | B9: 0 | C9: Bash timeout value in seconds. Leave blank for no change. Range: 0-99999. Set to 0 disables bash timeout. FOS default: 0
A10: Session Timeout | B10: 60 | C10: Session timeout value in seconds. Leave blank for no change. Range: 0-99999. Set to 0 disables SSH session timeout. Recommended is 60.
A11: TCP Timeout Level | B11: 5 | C11: Management interface timeout level. Leave blank for no change. Range: 1-5. FOS default and recommended: 5
A12: Max REST Sessions | B12: 3 | C12: Maximum number of REST sessions allowed. FOS default and recommended: 3.
A13: Configure Switches | B13: Yes | C13: Typically "Yes". Chassis processing stops and processing of Switch_x sheets begins.

Sheet Switch_x
A1: Area | B1: Parameter | C1: Comments
A3: Fabric ID (FID) | B3: 128 | C3: Required. FIDs are necessary for FOS to differentiate between logical switches in a chassis. Each logical switch in a chassis must have a unique FID and all logical switches in the same fabric must have the same FID. A FID can be any integer in the range 1 - 128. The recommended best practice is to use FID 128 for the default logical switch. Mainframe: not used in HCD or elsewhere but may appear in error messages.
A4: Enable/Disable | C4: Typically blank (empty cell) which indicates no change. Newly created logical switches are disabled by default. Switches are usually only disabled for service actions.
A5: Domain ID (DID) | B5: 0x01 | C5: Required unless modifying an existing switch. Empty indicates no change. DID must be in the range 1-0xEF. All switches in a fabric must have a unique DID. Mainframe: The DID is the high byte of the 2-byte address. The recommended best practice is to set the DID to match the Switch ID in HCD.
A6: Insistent DID | B6: Yes | C6: Best practice is "Yes". If the switch type is "ficon", insistent DID will be set regardless of what what is entered here.
A7: CLI | C7: CLI commands to send via SSH. Typically only used for service actions.
A8: Fabric Name | B8: Default_Fab_128 | C8: The recommended best practice is to name fabrics. Mainframe: not used in HCD or elsewhere but may appear in error messages.
A9: Switch Name | B9: Default_Switch_FID_128 | C9: User-friendly switch name. Best practice is to name all logical switches. Mainframe: not used in HCD or elsewhere but may appear in error messages.
A10: Fabric Principal | B10: Yes | C10: In fabrics consisting of mixed switch types, it is common to pick the switch on the most resilient and newest chassis. Moot in single switch fabrics or fabrics consisting of all the same switch types.
A11: Fabric Principal Priority | B11: 0x0A | C11: Only relevant if Fabric Principal Enable is "Yes". See FOS CLI fabricprincipal -priority for details. Best practice is 0x0A
A12: Allow XISL | C12: Typically "No". Select "Yes" to share ISLs in a base switch. This should also be "Yes" when creating a base switch.
A13: Login Banner | C13: Same as "Message Of The Day" on the "Chassis" sheet except <LF> is not permitted. This message is displayed when logging into an individual logical switches (setcontext) via the CLI.
A14: Switch Type | C14: Defines the switch type. Mainframe and AIX should always be "ficon".
A15: Duplicate WWN | C15: "first-flogi-or-first-fdisc-precedence" (default): The first FLOGI/FDISC are accepted. Subsequent logins for the same WWN are rejected elsewhere in the fabric. Use this for mainframe. Open may use this as well, but that depends on how storage fails-over. "second-flogi-or-secondfdisc-precedence": the second FLOGI/FDISC takes precedence, so the login where the first FLOGI/FDISC for the WWN occured is rejected. This may be used by some storage vendors for automatic fail-over. "first-flogi-or-second-fdisc-precedence": First FLOGI takes precedence but second FDISC takes precedence. This is the most common setting for open systems automatic storage fail-over. This is what allows the storage controller to present WWNs on different ports when there is a port failure. Check with your storage vendor if your not sure.
A16: Bind | C16: Should be "Yes" for mainframe and AIX. Should be "No" for all else. Exceptions are for those with expert knowledge.
A17: Routing Policy | C17: By default, FICON switches are created with DBR. All other switch types use EBR as the default routing policy. For mainframe, FICON, set this to EBR is if FiDR is desired.
A18: Port Name | C18: open: No switch wide port naming. Port names may be assigned using the "Slot x" worksheets. Maximum characters: 128. ficon: Same as "open", but characters are limited to 24 characters. index: Default. The port name corresponds to the port index. fdmi: The port name corresponds to the attached FDMI host name. Do not use for FICON. dynamic: The port name corresponds to the format defined by "Port Name Format". For FICON, this field is usually either "ficon" or empty.
A19: Port Name Format | C19: Only applicable if "Port Name" is "dynamic". Search the FOS Admin Guide for "Dynamic Port Name" for an explanation of "dynamic" or the Rest API Guide for "dynamic-portname-format".
A20: Enable/Disable | B20: Enable | C20: Typically "Enable". Typical placed before "Configure Ports" because ports can only be enabled if the switch is enabled.
A21: SCC | C21: Typically only used for FICON. An SCC policy is required for FICON. For FICON fabrics with multiple switches, cascaded, it is common for SAN administrators to wait until all switches are connected before implementing an SCC policy. Enter * for the WWNs of all switches in the fabric. Use a CSV list to manually add additional WWNs. The existing SCC policy is added to only. For more granualar SCC settings, use scc_policy.py.
A22: FICON Zone | C22: FICON only. Ignored if "Switch Type" is not "ficon". Launches mf_zone.py followed by zone_config.py. "all" is the most common zoning method for FICON. Execute "python mf_zone.py -eh" for an explanation of the different zoning options. Use mf_zone.py independantly to zone by channel.
A23: Enable CUP | C23: FICON only. Must be "Yes" if CUP is defined on any channel connected to this switch.
A24: Configure Ports | B24: Yes | C24: Typically "Yes". Switch_x processing stops and processing of Slot x sheets begins.

Sheet Slot 3
B1: SLOT 3
B2: Port | C2: DID (Hex) | D2: Port Addr (Hex) | E2: Index | F2: Link Addr | G2: FID | H2: Start Enable | I2: CLI | J2: End Enable | K2: Attached Device | L2: Port Name | M2: Low Qos VC | N2: Med Qos VC | O2: High Qos VC | Q2: Port | R2: DID (Hex) | S2: Port Addr (Hex) | T2: Index | U2: Link Addr | V2: FID | W2: Start Enable | X2: CLI | Y2: End Enable | Z2: Attached Device | AA2: Port Name | AB2: Low Qos VC | AC2: Med Qos VC | AD2: High Qos VC
B4: =B5+1 -> 23 | C4: =C5 -> 1 | D4: =DEC2HEX(HEX2DEC(D5)+1) -> 17 | E4: =E5+1 -> 23 | F4: =IF(HEX2DEC(D4)>15,IF(HEX2DEC(C4) > 15,CONCATENATE(C4,D4),CONCATENATE("0",C4,D4)),IF(HEX2DEC(C4) > 15,CONCATENATE(C4,"0",D4),CONCATENATE("0",C4,"0",D4))) -> 0117 | G4: =G5 -> 0 | M4: =LOOKUP(HEX2DEC(MID(F4,4,1)),VC!A1:C16) -> 9 | N4: =LOOKUP(HEX2DEC(MID(F4,4,1)),VC!A1:B16) -> 5 | O4: =LOOKUP(HEX2DEC(MID(F4,4,1)),VC!A1:D16) -> 12 | Q4: =Q5+1 -> 47 | R4: =R5 -> 1 | S4: =DEC2HEX(HEX2DEC(S5)+1) -> 2F | T4: =T5+1 -> 47 | U4: =IF(HEX2DEC(S4)>15,IF(HEX2DEC(R4) > 15,CONCATENATE(R4,S4),CONCATENATE("0",R4,S4)),IF(HEX2DEC(R4) > 15,CONCATENATE(R4,"0",S4),CONCATENATE("0",R4,"0",S4))) -> 012F | V4: =V5 -> 0 | AB4: =LOOKUP(HEX2DEC(MID(U4,4,1)),VC!A1:C16) -> 9 | AC4: =LOOKUP(HEX2DEC(MID(U4,4,1)),VC!A1:B16) -> 5 | AD4: =LOOKUP(HEX2DEC(MID(U4,4,1)),VC!A1:D16) -> 10
B5: =B6+1 -> 22 | C5: =C6 -> 1 | D5: =DEC2HEX(HEX2DEC(D6)+1) -> 16 | E5: =E6+1 -> 22 | F5: =IF(HEX2DEC(D5)>15,IF(HEX2DEC(C5) > 15,CONCATENATE(C5,D5),CONCATENATE("0",C5,D5)),IF(HEX2DEC(C5) > 15,CONCATENATE(C5,"0",D5),CONCATENATE("0",C5,"0",D5))) -> 0116 | G5: =G6 -> 0 | M5: =LOOKUP(HEX2DEC(MID(F5,4,1)),VC!A1:C16) -> 8 | N5: =LOOKUP(HEX2DEC(MID(F5,4,1)),VC!A1:B16) -> 4 | O5: =LOOKUP(HEX2DEC(MID(F5,4,1)),VC!A1:D16) -> 11 | Q5: =Q6+1 -> 46 | R5: =R6 -> 1 | S5: =DEC2HEX(HEX2DEC(S6)+1) -> 2E | T5: =T6+1 -> 46 | U5: =IF(HEX2DEC(S5)>15,IF(HEX2DEC(R5) > 15,CONCATENATE(R5,S5),CONCATENATE("0",R5,S5)),IF(HEX2DEC(R5) > 15,CONCATENATE(R5,"0",S5),CONCATENATE("0",R5,"0",S5))) -> 012E | V5: =V6 -> 0 | AB5: =LOOKUP(HEX2DEC(MID(U5,4,1)),VC!A1:C16) -> 8 | AC5: =LOOKUP(HEX2DEC(MID(U5,4,1)),VC!A1:B16) -> 4 | AD5: =LOOKUP(HEX2DEC(MID(U5,4,1)),VC!A1:D16) -> 14
B6: =B7+1 -> 21 | C6: =C7 -> 1 | D6: =DEC2HEX(HEX2DEC(D7)+1) -> 15 | E6: =E7+1 -> 21 | F6: =IF(HEX2DEC(D6)>15,IF(HEX2DEC(C6) > 15,CONCATENATE(C6,D6),CONCATENATE("0",C6,D6)),IF(HEX2DEC(C6) > 15,CONCATENATE(C6,"0",D6),CONCATENATE("0",C6,"0",D6))) -> 0115 | G6: =G7 -> 0 | M6: =LOOKUP(HEX2DEC(MID(F6,4,1)),VC!A1:C16) -> 9 | N6: =LOOKUP(HEX2DEC(MID(F6,4,1)),VC!A1:B16) -> 3 | O6: =LOOKUP(HEX2DEC(MID(F6,4,1)),VC!A1:D16) -> 10 | Q6: =Q7+1 -> 45 | R6: =R7 -> 1 | S6: =DEC2HEX(HEX2DEC(S7)+1) -> 2D | T6: =T7+1 -> 45 | U6: =IF(HEX2DEC(S6)>15,IF(HEX2DEC(R6) > 15,CONCATENATE(R6,S6),CONCATENATE("0",R6,S6)),IF(HEX2DEC(R6) > 15,CONCATENATE(R6,"0",S6),CONCATENATE("0",R6,"0",S6))) -> 012D | V6: =V7 -> 0 | AB6: =LOOKUP(HEX2DEC(MID(U6,4,1)),VC!A1:C16) -> 9 | AC6: =LOOKUP(HEX2DEC(MID(U6,4,1)),VC!A1:B16) -> 3 | AD6: =LOOKUP(HEX2DEC(MID(U6,4,1)),VC!A1:D16) -> 13
B7: =B8+1 -> 20 | C7: =C8 -> 1 | D7: =DEC2HEX(HEX2DEC(D8)+1) -> 14 | E7: =E8+1 -> 20 | F7: =IF(HEX2DEC(D7)>15,IF(HEX2DEC(C7) > 15,CONCATENATE(C7,D7),CONCATENATE("0",C7,D7)),IF(HEX2DEC(C7) > 15,CONCATENATE(C7,"0",D7),CONCATENATE("0",C7,"0",D7))) -> 0114 | G7: =G8 -> 0 | M7: =LOOKUP(HEX2DEC(MID(F7,4,1)),VC!A1:C16) -> 8 | N7: =LOOKUP(HEX2DEC(MID(F7,4,1)),VC!A1:B16) -> 2 | O7: =LOOKUP(HEX2DEC(MID(F7,4,1)),VC!A1:D16) -> 14 | Q7: =Q8+1 -> 44 | R7: =R8 -> 1 | S7: =DEC2HEX(HEX2DEC(S8)+1) -> 2C | T7: =T8+1 -> 44 | U7: =IF(HEX2DEC(S7)>15,IF(HEX2DEC(R7) > 15,CONCATENATE(R7,S7),CONCATENATE("0",R7,S7)),IF(HEX2DEC(R7) > 15,CONCATENATE(R7,"0",S7),CONCATENATE("0",R7,"0",S7))) -> 012C | V7: =V8 -> 0 | AB7: =LOOKUP(HEX2DEC(MID(U7,4,1)),VC!A1:C16) -> 8 | AC7: =LOOKUP(HEX2DEC(MID(U7,4,1)),VC!A1:B16) -> 2 | AD7: =LOOKUP(HEX2DEC(MID(U7,4,1)),VC!A1:D16) -> 12
B8: =B9+1 -> 19 | C8: =C9 -> 1 | D8: =DEC2HEX(HEX2DEC(D9)+1) -> 13 | E8: =E9+1 -> 19 | F8: =IF(HEX2DEC(D8)>15,IF(HEX2DEC(C8) > 15,CONCATENATE(C8,D8),CONCATENATE("0",C8,D8)),IF(HEX2DEC(C8) > 15,CONCATENATE(C8,"0",D8),CONCATENATE("0",C8,"0",D8))) -> 0113 | G8: =G9 -> 0 | M8: =LOOKUP(HEX2DEC(MID(F8,4,1)),VC!A1:C16) -> 9 | N8: =LOOKUP(HEX2DEC(MID(F8,4,1)),VC!A1:B16) -> 5 | O8: =LOOKUP(HEX2DEC(MID(F8,4,1)),VC!A1:D16) -> 13 | Q8: =Q9+1 -> 43 | R8: =R9 -> 1 | S8: =DEC2HEX(HEX2DEC(S9)+1) -> 2B | T8: =T9+1 -> 43 | U8: =IF(HEX2DEC(S8)>15,IF(HEX2DEC(R8) > 15,CONCATENATE(R8,S8),CONCATENATE("0",R8,S8)),IF(HEX2DEC(R8) > 15,CONCATENATE(R8,"0",S8),CONCATENATE("0",R8,"0",S8))) -> 012B | V8: =V9 -> 0 | AB8: =LOOKUP(HEX2DEC(MID(U8,4,1)),VC!A1:C16) -> 9 | AC8: =LOOKUP(HEX2DEC(MID(U8,4,1)),VC!A1:B16) -> 5 | AD8: =LOOKUP(HEX2DEC(MID(U8,4,1)),VC!A1:D16) -> 11
B9: =B10+1 -> 18 | C9: =C10 -> 1 | D9: =DEC2HEX(HEX2DEC(D10)+1) -> 12 | E9: =E10+1 -> 18 | F9: =IF(HEX2DEC(D9)>15,IF(HEX2DEC(C9) > 15,CONCATENATE(C9,D9),CONCATENATE("0",C9,D9)),IF(HEX2DEC(C9) > 15,CONCATENATE(C9,"0",D9),CONCATENATE("0",C9,"0",D9))) -> 0112 | G9: =G10 -> 0 | M9: =LOOKUP(HEX2DEC(MID(F9,4,1)),VC!A1:C16) -> 8 | N9: =LOOKUP(HEX2DEC(MID(F9,4,1)),VC!A1:B16) -> 4 | O9: =LOOKUP(HEX2DEC(MID(F9,4,1)),VC!A1:D16) -> 12 | Q9: =Q10+1 -> 42 | R9: =R10 -> 1 | S9: =DEC2HEX(HEX2DEC(S10)+1) -> 2A | T9: =T10+1 -> 42 | U9: =IF(HEX2DEC(S9)>15,IF(HEX2DEC(R9) > 15,CONCATENATE(R9,S9),CONCATENATE("0",R9,S9)),IF(HEX2DEC(R9) > 15,CONCATENATE(R9,"0",S9),CONCATENATE("0",R9,"0",S9))) -> 012A | V9: =V10 -> 0 | AB9: =LOOKUP(HEX2DEC(MID(U9,4,1)),VC!A1:C16) -> 8 | AC9: =LOOKUP(HEX2DEC(MID(U9,4,1)),VC!A1:B16) -> 4 | AD9: =LOOKUP(HEX2DEC(MID(U9,4,1)),VC!A1:D16) -> 10
B10: =B11+1 -> 17 | C10: =C11 -> 1 | D10: =DEC2HEX(HEX2DEC(D11)+1) -> 11 | E10: =E11+1 -> 17 | F10: =IF(HEX2DEC(D10)>15,IF(HEX2DEC(C10) > 15,CONCATENATE(C10,D10),CONCATENATE("0",C10,D10)),IF(HEX2DEC(C10) > 15,CONCATENATE(C10,"0",D10),CONCATENATE("0",C10,"0",D10))) -> 0111 | G10: =G11 -> 0 | M10: =LOOKUP(HEX2DEC(MID(F10,4,1)),VC!A1:C16) -> 9 | N10: =LOOKUP(HEX2DEC(MID(F10,4,1)),VC!A1:B16) -> 3 | O10: =LOOKUP(HEX2DEC(MID(F10,4,1)),VC!A1:D16) -> 11 | Q10: =Q11+1 -> 41 | R10: =R11 -> 1 | S10: =DEC2HEX(HEX2DEC(S11)+1) -> 29 | T10: =T11+1 -> 41 | U10: =IF(HEX2DEC(S10)>15,IF(HEX2DEC(R10) > 15,CONCATENATE(R10,S10),CONCATENATE("0",R10,S10)),IF(HEX2DEC(R10) > 15,CONCATENATE(R10,"0",S10),CONCATENATE("0",R10,"0",S10))) -> 0129 | V10: =V11 -> 0 | AB10: =LOOKUP(HEX2DEC(MID(U10,4,1)),VC!A1:C16) -> 9 | AC10: =LOOKUP(HEX2DEC(MID(U10,4,1)),VC!A1:B16) -> 3 | AD10: =LOOKUP(HEX2DEC(MID(U10,4,1)),VC!A1:D16) -> 14
B11: =B12+1 -> 16 | C11: =C12 -> 1 | D11: =DEC2HEX(HEX2DEC(D12)+1) -> 10 | E11: =E12+1 -> 16 | F11: =IF(HEX2DEC(D11)>15,IF(HEX2DEC(C11) > 15,CONCATENATE(C11,D11),CONCATENATE("0",C11,D11)),IF(HEX2DEC(C11) > 15,CONCATENATE(C11,"0",D11),CONCATENATE("0",C11,"0",D11))) -> 0110 | G11: =G12 -> 0 | M11: =LOOKUP(HEX2DEC(MID(F11,4,1)),VC!A1:C16) -> 8 | N11: =LOOKUP(HEX2DEC(MID(F11,4,1)),VC!A1:B16) -> 2 | O11: =LOOKUP(HEX2DEC(MID(F11,4,1)),VC!A1:D16) -> 10 | Q11: =Q12+1 -> 40 | R11: =R12 -> 1 | S11: =DEC2HEX(HEX2DEC(S12)+1) -> 28 | T11: =T12+1 -> 40 | U11: =IF(HEX2DEC(S11)>15,IF(HEX2DEC(R11) > 15,CONCATENATE(R11,S11),CONCATENATE("0",R11,S11)),IF(HEX2DEC(R11) > 15,CONCATENATE(R11,"0",S11),CONCATENATE("0",R11,"0",S11))) -> 0128 | V11: =V12 -> 0 | AB11: =LOOKUP(HEX2DEC(MID(U11,4,1)),VC!A1:C16) -> 8 | AC11: =LOOKUP(HEX2DEC(MID(U11,4,1)),VC!A1:B16) -> 2 | AD11: =LOOKUP(HEX2DEC(MID(U11,4,1)),VC!A1:D16) -> 13
B12: =B13+1 -> 15 | C12: =C13 -> 1 | D12: =DEC2HEX(HEX2DEC(D13)+1) -> F | E12: =E13+1 -> 15 | F12: =IF(HEX2DEC(D12)>15,IF(HEX2DEC(C12) > 15,CONCATENATE(C12,D12),CONCATENATE("0",C12,D12)),IF(HEX2DEC(C12) > 15,CONCATENATE(C12,"0",D12),CONCATENATE("0",C12,"0",D12))) -> 010F | G12: =G13 -> 0 | M12: =LOOKUP(HEX2DEC(MID(F12,4,1)),VC!A1:C16) -> 9 | N12: =LOOKUP(HEX2DEC(MID(F12,4,1)),VC!A1:B16) -> 5 | O12: =LOOKUP(HEX2DEC(MID(F12,4,1)),VC!A1:D16) -> 10 | Q12: =Q13+1 -> 39 | R12: =R13 -> 1 | S12: =DEC2HEX(HEX2DEC(S13)+1) -> 27 | T12: =T13+1 -> 39 | U12: =IF(HEX2DEC(S12)>15,IF(HEX2DEC(R12) > 15,CONCATENATE(R12,S12),CONCATENATE("0",R12,S12)),IF(HEX2DEC(R12) > 15,CONCATENATE(R12,"0",S12),CONCATENATE("0",R12,"0",S12))) -> 0127 | V12: =V13 -> 0 | AB12: =LOOKUP(HEX2DEC(MID(U12,4,1)),VC!A1:C16) -> 9 | AC12: =LOOKUP(HEX2DEC(MID(U12,4,1)),VC!A1:B16) -> 5 | AD12: =LOOKUP(HEX2DEC(MID(U12,4,1)),VC!A1:D16) -> 12
B13: =B14+1 -> 14 | C13: =C14 -> 1 | D13: =DEC2HEX(HEX2DEC(D14)+1) -> E | E13: =E14+1 -> 14 | F13: =IF(HEX2DEC(D13)>15,IF(HEX2DEC(C13) > 15,CONCATENATE(C13,D13),CONCATENATE("0",C13,D13)),IF(HEX2DEC(C13) > 15,CONCATENATE(C13,"0",D13),CONCATENATE("0",C13,"0",D13))) -> 010E | G13: =G14 -> 0 | M13: =LOOKUP(HEX2DEC(MID(F13,4,1)),VC!A1:C16) -> 8 | N13: =LOOKUP(HEX2DEC(MID(F13,4,1)),VC!A1:B16) -> 4 | O13: =LOOKUP(HEX2DEC(MID(F13,4,1)),VC!A1:D16) -> 14 | Q13: =Q14+1 -> 38 | R13: =R14 -> 1 | S13: =DEC2HEX(HEX2DEC(S14)+1) -> 26 | T13: =T14+1 -> 38 | U13: =IF(HEX2DEC(S13)>15,IF(HEX2DEC(R13) > 15,CONCATENATE(R13,S13),CONCATENATE("0",R13,S13)),IF(HEX2DEC(R13) > 15,CONCATENATE(R13,"0",S13),CONCATENATE("0",R13,"0",S13))) -> 0126 | V13: =V14 -> 0 | AB13: =LOOKUP(HEX2DEC(MID(U13,4,1)),VC!A1:C16) -> 8 | AC13: =LOOKUP(HEX2DEC(MID(U13,4,1)),VC!A1:B16) -> 4 | AD13: =LOOKUP(HEX2DEC(MID(U13,4,1)),VC!A1:D16) -> 11
B14: =B15+1 -> 13 | C14: =C15 -> 1 | D14: =DEC2HEX(HEX2DEC(D15)+1) -> D | E14: =E15+1 -> 13 | F14: =IF(HEX2DEC(D14)>15,IF(HEX2DEC(C14) > 15,CONCATENATE(C14,D14),CONCATENATE("0",C14,D14)),IF(HEX2DEC(C14) > 15,CONCATENATE(C14,"0",D14),CONCATENATE("0",C14,"0",D14))) -> 010D | G14: =G15 -> 0 | M14: =LOOKUP(HEX2DEC(MID(F14,4,1)),VC!A1:C16) -> 9 | N14: =LOOKUP(HEX2DEC(MID(F14,4,1)),VC!A1:B16) -> 3 | O14: =LOOKUP(HEX2DEC(MID(F14,4,1)),VC!A1:D16) -> 13 | Q14: =Q15+1 -> 37 | R14: =R15 -> 1 | S14: =DEC2HEX(HEX2DEC(S15)+1) -> 25 | T14: =T15+1 -> 37 | U14: =IF(HEX2DEC(S14)>15,IF(HEX2DEC(R14) > 15,CONCATENATE(R14,S14),CONCATENATE("0",R14,S14)),IF(HEX2DEC(R14) > 15,CONCATENATE(R14,"0",S14),CONCATENATE("0",R14,"0",S14))) -> 0125 | V14: =V15 -> 0 | AB14: =LOOKUP(HEX2DEC(MID(U14,4,1)),VC!A1:C16) -> 9 | AC14: =LOOKUP(HEX2DEC(MID(U14,4,1)),VC!A1:B16) -> 3 | AD14: =LOOKUP(HEX2DEC(MID(U14,4,1)),VC!A1:D16) -> 10
B15: =B16+1 -> 12 | C15: =C16 -> 1 | D15: =DEC2HEX(HEX2DEC(D16)+1) -> C | E15: =E16+1 -> 12 | F15: =IF(HEX2DEC(D15)>15,IF(HEX2DEC(C15) > 15,CONCATENATE(C15,D15),CONCATENATE("0",C15,D15)),IF(HEX2DEC(C15) > 15,CONCATENATE(C15,"0",D15),CONCATENATE("0",C15,"0",D15))) -> 010C | G15: =G16 -> 0 | M15: =LOOKUP(HEX2DEC(MID(F15,4,1)),VC!A1:C16) -> 8 | N15: =LOOKUP(HEX2DEC(MID(F15,4,1)),VC!A1:B16) -> 2 | O15: =LOOKUP(HEX2DEC(MID(F15,4,1)),VC!A1:D16) -> 12 | Q15: =Q16+1 -> 36 | R15: =R16 -> 1 | S15: =DEC2HEX(HEX2DEC(S16)+1) -> 24 | T15: =T16+1 -> 36 | U15: =IF(HEX2DEC(S15)>15,IF(HEX2DEC(R15) > 15,CONCATENATE(R15,S15),CONCATENATE("0",R15,S15)),IF(HEX2DEC(R15) > 15,CONCATENATE(R15,"0",S15),CONCATENATE("0",R15,"0",S15))) -> 0124 | V15: =V16 -> 0 | AB15: =LOOKUP(HEX2DEC(MID(U15,4,1)),VC!A1:C16) -> 8 | AC15: =LOOKUP(HEX2DEC(MID(U15,4,1)),VC!A1:B16) -> 2 | AD15: =LOOKUP(HEX2DEC(MID(U15,4,1)),VC!A1:D16) -> 14
B16: =B17+1 -> 11 | C16: =C17 -> 1 | D16: =DEC2HEX(HEX2DEC(D17)+1) -> B | E16: =E17+1 -> 11 | F16: =IF(HEX2DEC(D16)>15,IF(HEX2DEC(C16) > 15,CONCATENATE(C16,D16),CONCATENATE("0",C16,D16)),IF(HEX2DEC(C16) > 15,CONCATENATE(C16,"0",D16),CONCATENATE("0",C16,"0",D16))) -> 010B | G16: =G17 -> 0 | M16: =LOOKUP(HEX2DEC(MID(F16,4,1)),VC!A1:C16) -> 9 | N16: =LOOKUP(HEX2DEC(MID(F16,4,1)),VC!A1:B16) -> 5 | O16: =LOOKUP(HEX2DEC(MID(F16,4,1)),VC!A1:D16) -> 11 | Q16: =Q17+1 -> 35 | R16: =R17 -> 1 | S16: =DEC2HEX(HEX2DEC(S17)+1) -> 23 | T16: =T17+1 -> 35 | U16: =IF(HEX2DEC(S16)>15,IF(HEX2DEC(R16) > 15,CONCATENATE(R16,S16),CONCATENATE("0",R16,S16)),IF(HEX2DEC(R16) > 15,CONCATENATE(R16,"0",S16),CONCATENATE("0",R16,"0",S16))) -> 0123 | V16: =V17 -> 0 | AB16: =LOOKUP(HEX2DEC(MID(U16,4,1)),VC!A1:C16) -> 9 | AC16: =LOOKUP(HEX2DEC(MID(U16,4,1)),VC!A1:B16) -> 5 | AD16: =LOOKUP(HEX2DEC(MID(U16,4,1)),VC!A1:D16) -> 13
B17: =B18+1 -> 10 | C17: =C18 -> 1 | D17: =DEC2HEX(HEX2DEC(D18)+1) -> A | E17: =E18+1 -> 10 | F17: =IF(HEX2DEC(D17)>15,IF(HEX2DEC(C17) > 15,CONCATENATE(C17,D17),CONCATENATE("0",C17,D17)),IF(HEX2DEC(C17) > 15,CONCATENATE(C17,"0",D17),CONCATENATE("0",C17,"0",D17))) -> 010A | G17: =G18 -> 0 | M17: =LOOKUP(HEX2DEC(MID(F17,4,1)),VC!A1:C16) -> 8 | N17: =LOOKUP(HEX2DEC(MID(F17,4,1)),VC!A1:B16) -> 4 | O17: =LOOKUP(HEX2DEC(MID(F17,4,1)),VC!A1:D16) -> 10 | Q17: =Q18+1 -> 34 | R17: =R18 -> 1 | S17: =DEC2HEX(HEX2DEC(S18)+1) -> 22 | T17: =T18+1 -> 34 | U17: =IF(HEX2DEC(S17)>15,IF(HEX2DEC(R17) > 15,CONCATENATE(R17,S17),CONCATENATE("0",R17,S17)),IF(HEX2DEC(R17) > 15,CONCATENATE(R17,"0",S17),CONCATENATE("0",R17,"0",S17))) -> 0122 | V17: =V18 -> 0 | AB17: =LOOKUP(HEX2DEC(MID(U17,4,1)),VC!A1:C16) -> 8 | AC17: =LOOKUP(HEX2DEC(MID(U17,4,1)),VC!A1:B16) -> 4 | AD17: =LOOKUP(HEX2DEC(MID(U17,4,1)),VC!A1:D16) -> 12
B18: =B19+1 -> 9 | C18: =C19 -> 1 | D18: =DEC2HEX(HEX2DEC(D19)+1) -> 9 | E18: =E19+1 -> 9 | F18: =IF(HEX2DEC(D18)>15,IF(HEX2DEC(C18) > 15,CONCATENATE(C18,D18),CONCATENATE("0",C18,D18)),IF(HEX2DEC(C18) > 15,CONCATENATE(C18,"0",D18),CONCATENATE("0",C18,"0",D18))) -> 0109 | G18: =G19 -> 0 | M18: =LOOKUP(HEX2DEC(MID(F18,4,1)),VC!A1:C16) -> 9 | N18: =LOOKUP(HEX2DEC(MID(F18,4,1)),VC!A1:B16) -> 3 | O18: =LOOKUP(HEX2DEC(MID(F18,4,1)),VC!A1:D16) -> 14 | Q18: =Q19+1 -> 33 | R18: =R19 -> 1 | S18: =DEC2HEX(HEX2DEC(S19)+1) -> 21 | T18: =T19+1 -> 33 | U18: =IF(HEX2DEC(S18)>15,IF(HEX2DEC(R18) > 15,CONCATENATE(R18,S18),CONCATENATE("0",R18,S18)),IF(HEX2DEC(R18) > 15,CONCATENATE(R18,"0",S18),CONCATENATE("0",R18,"0",S18))) -> 0121 | V18: =V19 -> 0 | AB18: =LOOKUP(HEX2DEC(MID(U18,4,1)),VC!A1:C16) -> 9 | AC18: =LOOKUP(HEX2DEC(MID(U18,4,1)),VC!A1:B16) -> 3 | AD18: =LOOKUP(HEX2DEC(MID(U18,4,1)),VC!A1:D16) -> 11
B19: =B20+1 -> 8 | C19: =C20 -> 1 | D19: =DEC2HEX(HEX2DEC(D20)+1) -> 8 | E19: =E20+1 -> 8 | F19: =IF(HEX2DEC(D19)>15,IF(HEX2DEC(C19) > 15,CONCATENATE(C19,D19),CONCATENATE("0",C19,D19)),IF(HEX2DEC(C19) > 15,CONCATENATE(C19,"0",D19),CONCATENATE("0",C19,"0",D19))) -> 0108 | G19: =G20 -> 0 | M19: =LOOKUP(HEX2DEC(MID(F19,4,1)),VC!A1:C16) -> 8 | N19: =LOOKUP(HEX2DEC(MID(F19,4,1)),VC!A1:B16) -> 2 | O19: =LOOKUP(HEX2DEC(MID(F19,4,1)),VC!A1:D16) -> 13 | Q19: =Q20+1 -> 32 | R19: =R20 -> 1 | S19: =DEC2HEX(HEX2DEC(S20)+1) -> 20 | T19: =T20+1 -> 32 | U19: =IF(HEX2DEC(S19)>15,IF(HEX2DEC(R19) > 15,CONCATENATE(R19,S19),CONCATENATE("0",R19,S19)),IF(HEX2DEC(R19) > 15,CONCATENATE(R19,"0",S19),CONCATENATE("0",R19,"0",S19))) -> 0120 | V19: =V20 -> 0 | AB19: =LOOKUP(HEX2DEC(MID(U19,4,1)),VC!A1:C16) -> 8 | AC19: =LOOKUP(HEX2DEC(MID(U19,4,1)),VC!A1:B16) -> 2 | AD19: =LOOKUP(HEX2DEC(MID(U19,4,1)),VC!A1:D16) -> 10
B20: =B21+1 -> 7 | C20: =C21 -> 1 | D20: =DEC2HEX(HEX2DEC(D21)+1) -> 7 | E20: =E21+1 -> 7 | F20: =IF(HEX2DEC(D20)>15,IF(HEX2DEC(C20) > 15,CONCATENATE(C20,D20),CONCATENATE("0",C20,D20)),IF(HEX2DEC(C20) > 15,CONCATENATE(C20,"0",D20),CONCATENATE("0",C20,"0",D20))) -> 0107 | G20: =G21 -> 0 | M20: =LOOKUP(HEX2DEC(MID(F20,4,1)),VC!A1:C16) -> 9 | N20: =LOOKUP(HEX2DEC(MID(F20,4,1)),VC!A1:B16) -> 5 | O20: =LOOKUP(HEX2DEC(MID(F20,4,1)),VC!A1:D16) -> 12 | Q20: =Q21+1 -> 31 | R20: =R21 -> 1 | S20: =DEC2HEX(HEX2DEC(S21)+1) -> 1F | T20: =T21+1 -> 31 | U20: =IF(HEX2DEC(S20)>15,IF(HEX2DEC(R20) > 15,CONCATENATE(R20,S20),CONCATENATE("0",R20,S20)),IF(HEX2DEC(R20) > 15,CONCATENATE(R20,"0",S20),CONCATENATE("0",R20,"0",S20))) -> 011F | V20: =V21 -> 0 | AB20: =LOOKUP(HEX2DEC(MID(U20,4,1)),VC!A1:C16) -> 9 | AC20: =LOOKUP(HEX2DEC(MID(U20,4,1)),VC!A1:B16) -> 5 | AD20: =LOOKUP(HEX2DEC(MID(U20,4,1)),VC!A1:D16) -> 10
B21: =B22+1 -> 6 | C21: =C22 -> 1 | D21: =DEC2HEX(HEX2DEC(D22)+1) -> 6 | E21: =E22+1 -> 6 | F21: =IF(HEX2DEC(D21)>15,IF(HEX2DEC(C21) > 15,CONCATENATE(C21,D21),CONCATENATE("0",C21,D21)),IF(HEX2DEC(C21) > 15,CONCATENATE(C21,"0",D21),CONCATENATE("0",C21,"0",D21))) -> 0106 | G21: =G22 -> 0 | M21: =LOOKUP(HEX2DEC(MID(F21,4,1)),VC!A1:C16) -> 8 | N21: =LOOKUP(HEX2DEC(MID(F21,4,1)),VC!A1:B16) -> 4 | O21: =LOOKUP(HEX2DEC(MID(F21,4,1)),VC!A1:D16) -> 11 | Q21: =Q22+1 -> 30 | R21: =R22 -> 1 | S21: =DEC2HEX(HEX2DEC(S22)+1) -> 1E | T21: =T22+1 -> 30 | U21: =IF(HEX2DEC(S21)>15,IF(HEX2DEC(R21) > 15,CONCATENATE(R21,S21),CONCATENATE("0",R21,S21)),IF(HEX2DEC(R21) > 15,CONCATENATE(R21,"0",S21),CONCATENATE("0",R21,"0",S21))) -> 011E | V21: =V22 -> 0 | AB21: =LOOKUP(HEX2DEC(MID(U21,4,1)),VC!A1:C16) -> 8 | AC21: =LOOKUP(HEX2DEC(MID(U21,4,1)),VC!A1:B16) -> 4 | AD21: =LOOKUP(HEX2DEC(MID(U21,4,1)),VC!A1:D16) -> 14
B22: =B23+1 -> 5 | C22: =C23 -> 1 | D22: =DEC2HEX(HEX2DEC(D23)+1) -> 5 | E22: =E23+1 -> 5 | F22: =IF(HEX2DEC(D22)>15,IF(HEX2DEC(C22) > 15,CONCATENATE(C22,D22),CONCATENATE("0",C22,D22)),IF(HEX2DEC(C22) > 15,CONCATENATE(C22,"0",D22),CONCATENATE("0",C22,"0",D22))) -> 0105 | G22: =G23 -> 0 | M22: =LOOKUP(HEX2DEC(MID(F22,4,1)),VC!A1:C16) -> 9 | N22: =LOOKUP(HEX2DEC(MID(F22,4,1)),VC!A1:B16) -> 3 | O22: =LOOKUP(HEX2DEC(MID(F22,4,1)),VC!A1:D16) -> 10 | Q22: =Q23+1 -> 29 | R22: =R23 -> 1 | S22: =DEC2HEX(HEX2DEC(S23)+1) -> 1D | T22: =T23+1 -> 29 | U22: =IF(HEX2DEC(S22)>15,IF(HEX2DEC(R22) > 15,CONCATENATE(R22,S22),CONCATENATE("0",R22,S22)),IF(HEX2DEC(R22) > 15,CONCATENATE(R22,"0",S22),CONCATENATE("0",R22,"0",S22))) -> 011D | V22: =V23 -> 0 | AB22: =LOOKUP(HEX2DEC(MID(U22,4,1)),VC!A1:C16) -> 9 | AC22: =LOOKUP(HEX2DEC(MID(U22,4,1)),VC!A1:B16) -> 3 | AD22: =LOOKUP(HEX2DEC(MID(U22,4,1)),VC!A1:D16) -> 13
B23: =B24+1 -> 4 | C23: =C24 -> 1 | D23: =DEC2HEX(HEX2DEC(D24)+1) -> 4 | E23: =E24+1 -> 4 | F23: =IF(HEX2DEC(D23)>15,IF(HEX2DEC(C23) > 15,CONCATENATE(C23,D23),CONCATENATE("0",C23,D23)),IF(HEX2DEC(C23) > 15,CONCATENATE(C23,"0",D23),CONCATENATE("0",C23,"0",D23))) -> 0104 | G23: =G24 -> 0 | M23: =LOOKUP(HEX2DEC(MID(F23,4,1)),VC!A1:C16) -> 8 | N23: =LOOKUP(HEX2DEC(MID(F23,4,1)),VC!A1:B16) -> 2 | O23: =LOOKUP(HEX2DEC(MID(F23,4,1)),VC!A1:D16) -> 14 | Q23: =Q24+1 -> 28 | R23: =R24 -> 1 | S23: =DEC2HEX(HEX2DEC(S24)+1) -> 1C | T23: =T24+1 -> 28 | U23: =IF(HEX2DEC(S23)>15,IF(HEX2DEC(R23) > 15,CONCATENATE(R23,S23),CONCATENATE("0",R23,S23)),IF(HEX2DEC(R23) > 15,CONCATENATE(R23,"0",S23),CONCATENATE("0",R23,"0",S23))) -> 011C | V23: =V24 -> 0 | AB23: =LOOKUP(HEX2DEC(MID(U23,4,1)),VC!A1:C16) -> 8 | AC23: =LOOKUP(HEX2DEC(MID(U23,4,1)),VC!A1:B16) -> 2 | AD23: =LOOKUP(HEX2DEC(MID(U23,4,1)),VC!A1:D16) -> 12
B24: =B25+1 -> 3 | C24: =C25 -> 1 | D24: =DEC2HEX(HEX2DEC(D25)+1) -> 3 | E24: =E25+1 -> 3 | F24: =IF(HEX2DEC(D24)>15,IF(HEX2DEC(C24) > 15,CONCATENATE(C24,D24),CONCATENATE("0",C24,D24)),IF(HEX2DEC(C24) > 15,CONCATENATE(C24,"0",D24),CONCATENATE("0",C24,"0",D24))) -> 0103 | G24: =G25 -> 0 | M24: =LOOKUP(HEX2DEC(MID(F24,4,1)),VC!A1:C16) -> 9 | N24: =LOOKUP(HEX2DEC(MID(F24,4,1)),VC!A1:B16) -> 5 | O24: =LOOKUP(HEX2DEC(MID(F24,4,1)),VC!A1:D16) -> 13 | Q24: =Q25+1 -> 27 | R24: =R25 -> 1 | S24: =DEC2HEX(HEX2DEC(S25)+1) -> 1B | T24: =T25+1 -> 27 | U24: =IF(HEX2DEC(S24)>15,IF(HEX2DEC(R24) > 15,CONCATENATE(R24,S24),CONCATENATE("0",R24,S24)),IF(HEX2DEC(R24) > 15,CONCATENATE(R24,"0",S24),CONCATENATE("0",R24,"0",S24))) -> 011B | V24: =V25 -> 0 | AB24: =LOOKUP(HEX2DEC(MID(U24,4,1)),VC!A1:C16) -> 9 | AC24: =LOOKUP(HEX2DEC(MID(U24,4,1)),VC!A1:B16) -> 5 | AD24: =LOOKUP(HEX2DEC(MID(U24,4,1)),VC!A1:D16) -> 11
B25: =B26+1 -> 2 | C25: =C26 -> 1 | D25: =DEC2HEX(HEX2DEC(D26)+1) -> 2 | E25: =E26+1 -> 2 | F25: =IF(HEX2DEC(D25)>15,IF(HEX2DEC(C25) > 15,CONCATENATE(C25,D25),CONCATENATE("0",C25,D25)),IF(HEX2DEC(C25) > 15,CONCATENATE(C25,"0",D25),CONCATENATE("0",C25,"0",D25))) -> 0102 | G25: =G26 -> 0 | M25: =LOOKUP(HEX2DEC(MID(F25,4,1)),VC!A1:C16) -> 8 | N25: =LOOKUP(HEX2DEC(MID(F25,4,1)),VC!A1:B16) -> 4 | O25: =LOOKUP(HEX2DEC(MID(F25,4,1)),VC!A1:D16) -> 12 | Q25: =Q26+1 -> 26 | R25: =R26 -> 1 | S25: =DEC2HEX(HEX2DEC(S26)+1) -> 1A | T25: =T26+1 -> 26 | U25: =IF(HEX2DEC(S25)>15,IF(HEX2DEC(R25) > 15,CONCATENATE(R25,S25),CONCATENATE("0",R25,S25)),IF(HEX2DEC(R25) > 15,CONCATENATE(R25,"0",S25),CONCATENATE("0",R25,"0",S25))) -> 011A | V25: =V26 -> 0 | AB25: =LOOKUP(HEX2DEC(MID(U25,4,1)),VC!A1:C16) -> 8 | AC25: =LOOKUP(HEX2DEC(MID(U25,4,1)),VC!A1:B16) -> 4 | AD25: =LOOKUP(HEX2DEC(MID(U25,4,1)),VC!A1:D16) -> 10
B26: =B27+1 -> 1 | C26: =C27 -> 1 | D26: =DEC2HEX(HEX2DEC(D27)+1) -> 1 | E26: =E27+1 -> 1 | F26: =IF(HEX2DEC(D26)>15,IF(HEX2DEC(C26) > 15,CONCATENATE(C26,D26),CONCATENATE("0",C26,D26)),IF(HEX2DEC(C26) > 15,CONCATENATE(C26,"0",D26),CONCATENATE("0",C26,"0",D26))) -> 0101 | G26: =G27 -> 0 | M26: =LOOKUP(HEX2DEC(MID(F26,4,1)),VC!A1:C16) -> 9 | N26: =LOOKUP(HEX2DEC(MID(F26,4,1)),VC!A1:B16) -> 3 | O26: =LOOKUP(HEX2DEC(MID(F26,4,1)),VC!A1:D16) -> 11 | Q26: =Q27+1 -> 25 | R26: =R27 -> 1 | S26: =DEC2HEX(HEX2DEC(S27)+1) -> 19 | T26: =T27+1 -> 25 | U26: =IF(HEX2DEC(S26)>15,IF(HEX2DEC(R26) > 15,CONCATENATE(R26,S26),CONCATENATE("0",R26,S26)),IF(HEX2DEC(R26) > 15,CONCATENATE(R26,"0",S26),CONCATENATE("0",R26,"0",S26))) -> 0119 | V26: =V27 -> 0 | AB26: =LOOKUP(HEX2DEC(MID(U26,4,1)),VC!A1:C16) -> 9 | AC26: =LOOKUP(HEX2DEC(MID(U26,4,1)),VC!A1:B16) -> 3 | AD26: =LOOKUP(HEX2DEC(MID(U26,4,1)),VC!A1:D16) -> 14
B27: 0 | C27: =SUBSTITUTE(SUBSTITUTE(Switch_x!B5,"0x0",""),"0x","") -> 1 | D27: 0 | E27: 0 | F27: =IF(HEX2DEC(D27)>15,IF(HEX2DEC(C27) > 15,CONCATENATE(C27,D27),CONCATENATE("0",C27,D27)),IF(HEX2DEC(C27) > 15,CONCATENATE(C27,"0",D27),CONCATENATE("0",C27,"0",D27))) -> 0100 | G27: =Switch_x!B2 -> 0 | M27: =LOOKUP(HEX2DEC(MID(F27,4,1)),VC!A1:C16) -> 8 | N27: =LOOKUP(HEX2DEC(MID(F27,4,1)),VC!A1:B16) -> 2 | O27: =LOOKUP(HEX2DEC(MID(F27,4,1)),VC!A1:D16) -> 10 | Q27: =B4+1 -> 24 | R27: =C4 -> 1 | S27: =DEC2HEX(HEX2DEC(D4)+1) -> 18 | T27: =E4+1 -> 24 | U27: =IF(HEX2DEC(S27)>15,IF(HEX2DEC(R27) > 15,CONCATENATE(R27,S27),CONCATENATE("0",R27,S27)),IF(HEX2DEC(R27) > 15,CONCATENATE(R27,"0",S27),CONCATENATE("0",R27,"0",S27))) -> 0118 | V27: =G4 -> 0 | AB27: =LOOKUP(HEX2DEC(MID(U27,4,1)),VC!A1:C16) -> 8 | AC27: =LOOKUP(HEX2DEC(MID(U27,4,1)),VC!A1:B16) -> 2 | AD27: =LOOKUP(HEX2DEC(MID(U27,4,1)),VC!A1:D16) -> 13
F29: ASIC 0
F31: ASIC 1

Sheet Slot 4
B1: SLOT 4
B2: Port | C2: DID (Hex) | D2: Port Addr (Hex) | E2: Index | F2: Link Addr | G2: FID | H2: Start Enable | I2: CLI | J2: End Enable | K2: Attached Device | L2: Port Name | M2: Low Qos VC | N2: Med Qos VC | O2: High Qos VC | Q2: Port | R2: DID (Hex) | S2: Port Addr (Hex) | T2: Index | U2: Link Addr | V2: FID | W2: Start Enable | X2: CLI | Y2: End Enable | Z2: Attached Device | AA2: Port Name | AB2: Low Qos VC | AC2: Med Qos VC | AD2: High Qos VC
B4: =B5+1 -> 23 | C4: =C5 -> 1 | D4: =DEC2HEX(HEX2DEC(D5)+1) -> 47 | E4: =E5+1 -> 119 | F4: =IF(HEX2DEC(D4)>15,IF(HEX2DEC(C4) > 15,CONCATENATE(C4,D4),CONCATENATE("0",C4,D4)),IF(HEX2DEC(C4) > 15,CONCATENATE(C4,"0",D4),CONCATENATE("0",C4,"0",D4))) -> 0147 | G4: =G5 -> 0 | M4: =LOOKUP(HEX2DEC(MID(F4,4,1)),VC!A1:C16) -> 9 | N4: =LOOKUP(HEX2DEC(MID(F4,4,1)),VC!A1:B16) -> 5 | O4: =LOOKUP(HEX2DEC(MID(F4,4,1)),VC!A1:D16) -> 12 | Q4: =Q5+1 -> 47 | R4: =R5 -> 1 | S4: =DEC2HEX(HEX2DEC(S5)+1) -> 5F | T4: =T5+1 -> 143 | U4: =IF(HEX2DEC(S4)>15,IF(HEX2DEC(R4) > 15,CONCATENATE(R4,S4),CONCATENATE("0",R4,S4)),IF(HEX2DEC(R4) > 15,CONCATENATE(R4,"0",S4),CONCATENATE("0",R4,"0",S4))) -> 015F | V4: =V5 -> 0 | AB4: =LOOKUP(HEX2DEC(MID(U4,4,1)),VC!A1:C16) -> 9 | AC4: =LOOKUP(HEX2DEC(MID(U4,4,1)),VC!A1:B16) -> 5 | AD4: =LOOKUP(HEX2DEC(MID(U4,4,1)),VC!A1:D16) -> 10
B5: =B6+1 -> 22 | C5: =C6 -> 1 | D5: =DEC2HEX(HEX2DEC(D6)+1) -> 46 | E5: =E6+1 -> 118 | F5: =IF(HEX2DEC(D5)>15,IF(HEX2DEC(C5) > 15,CONCATENATE(C5,D5),CONCATENATE("0",C5,D5)),IF(HEX2DEC(C5) > 15,CONCATENATE(C5,"0",D5),CONCATENATE("0",C5,"0",D5))) -> 0146 | G5: =G6 -> 0 | M5: =LOOKUP(HEX2DEC(MID(F5,4,1)),VC!A1:C16) -> 8 | N5: =LOOKUP(HEX2DEC(MID(F5,4,1)),VC!A1:B16) -> 4 | O5: =LOOKUP(HEX2DEC(MID(F5,4,1)),VC!A1:D16) -> 11 | Q5: =Q6+1 -> 46 | R5: =R6 -> 1 | S5: =DEC2HEX(HEX2DEC(S6)+1) -> 5E | T5: =T6+1 -> 142 | U5: =IF(HEX2DEC(S5)>15,IF(HEX2DEC(R5) > 15,CONCATENATE(R5,S5),CONCATENATE("0",R5,S5)),IF(HEX2DEC(R5) > 15,CONCATENATE(R5,"0",S5),CONCATENATE("0",R5,"0",S5))) -> 015E | V5: =V6 -> 0 | AB5: =LOOKUP(HEX2DEC(MID(U5,4,1)),VC!A1:C16) -> 8 | AC5: =LOOKUP(HEX2DEC(MID(U5,4,1)),VC!A1:B16) -> 4 | AD5: =LOOKUP(HEX2DEC(MID(U5,4,1)),VC!A1:D16) -> 14
B6: =B7+1 -> 21 | C6: =C7 -> 1 | D6: =DEC2HEX(HEX2DEC(D7)+1) -> 45 | E6: =E7+1 -> 117 | F6: =IF(HEX2DEC(D6)>15,IF(HEX2DEC(C6) > 15,CONCATENATE(C6,D6),CONCATENATE("0",C6,D6)),IF(HEX2DEC(C6) > 15,CONCATENATE(C6,"0",D6),CONCATENATE("0",C6,"0",D6))) -> 0145 | G6: =G7 -> 0 | M6: =LOOKUP(HEX2DEC(MID(F6,4,1)),VC!A1:C16) -> 9 | N6: =LOOKUP(HEX2DEC(MID(F6,4,1)),VC!A1:B16) -> 3 | O6: =LOOKUP(HEX2DEC(MID(F6,4,1)),VC!A1:D16) -> 10 | Q6: =Q7+1 -> 45 | R6: =R7 -> 1 | S6: =DEC2HEX(HEX2DEC(S7)+1) -> 5D | T6: =T7+1 -> 141 | U6: =IF(HEX2DEC(S6)>15,IF(HEX2DEC(R6) > 15,CONCATENATE(R6,S6),CONCATENATE("0",R6,S6)),IF(HEX2DEC(R6) > 15,CONCATENATE(R6,"0",S6),CONCATENATE("0",R6,"0",S6))) -> 015D | V6: =V7 -> 0 | AB6: =LOOKUP(HEX2DEC(MID(U6,4,1)),VC!A1:C16) -> 9 | AC6: =LOOKUP(HEX2DEC(MID(U6,4,1)),VC!A1:B16) -> 3 | AD6: =LOOKUP(HEX2DEC(MID(U6,4,1)),VC!A1:D16) -> 13
B7: =B8+1 -> 20 | C7: =C8 -> 1 | D7: =DEC2HEX(HEX2DEC(D8)+1) -> 44 | E7: =E8+1 -> 116 | F7: =IF(HEX2DEC(D7)>15,IF(HEX2DEC(C7) > 15,CONCATENATE(C7,D7),CONCATENATE("0",C7,D7)),IF(HEX2DEC(C7) > 15,CONCATENATE(C7,"0",D7),CONCATENATE("0",C7,"0",D7))) -> 0144 | G7: =G8 -> 0 | M7: =LOOKUP(HEX2DEC(MID(F7,4,1)),VC!A1:C16) -> 8 | N7: =LOOKUP(HEX2DEC(MID(F7,4,1)),VC!A1:B16) -> 2 | O7: =LOOKUP(HEX2DEC(MID(F7,4,1)),VC!A1:D16) -> 14 | Q7: =Q8+1 -> 44 | R7: =R8 -> 1 | S7: =DEC2HEX(HEX2DEC(S8)+1) -> 5C | T7: =T8+1 -> 140 | U7: =IF(HEX2DEC(S7)>15,IF(HEX2DEC(R7) > 15,CONCATENATE(R7,S7),CONCATENATE("0",R7,S7)),IF(HEX2DEC(R7) > 15,CONCATENATE(R7,"0",S7),CONCATENATE("0",R7,"0",S7))) -> 015C | V7: =V8 -> 0 | AB7: =LOOKUP(HEX2DEC(MID(U7,4,1)),VC!A1:C16) -> 8 | AC7: =LOOKUP(HEX2DEC(MID(U7,4,1)),VC!A1:B16) -> 2 | AD7: =LOOKUP(HEX2DEC(MID(U7,4,1)),VC!A1:D16) -> 12
B8: =B9+1 -> 19 | C8: =C9 -> 1 | D8: =DEC2HEX(HEX2DEC(D9)+1) -> 43 | E8: =E9+1 -> 115 | F8: =IF(HEX2DEC(D8)>15,IF(HEX2DEC(C8) > 15,CONCATENATE(C8,D8),CONCATENATE("0",C8,D8)),IF(HEX2DEC(C8) > 15,CONCATENATE(C8,"0",D8),CONCATENATE("0",C8,"0",D8))) -> 0143 | G8: =G9 -> 0 | M8: =LOOKUP(HEX2DEC(MID(F8,4,1)),VC!A1:C16) -> 9 | N8: =LOOKUP(HEX2DEC(MID(F8,4,1)),VC!A1:B16) -> 5 | O8: =LOOKUP(HEX2DEC(MID(F8,4,1)),VC!A1:D16) -> 13 | Q8: =Q9+1 -> 43 | R8: =R9 -> 1 | S8: =DEC2HEX(HEX2DEC(S9)+1) -> 5B | T8: =T9+1 -> 139 | U8: =IF(HEX2DEC(S8)>15,IF(HEX2DEC(R8) > 15,CONCATENATE(R8,S8),CONCATENATE("0",R8,S8)),IF(HEX2DEC(R8) > 15,CONCATENATE(R8,"0",S8),CONCATENATE("0",R8,"0",S8))) -> 015B | V8: =V9 -> 0 | AB8: =LOOKUP(HEX2DEC(MID(U8,4,1)),VC!A1:C16) -> 9 | AC8: =LOOKUP(HEX2DEC(MID(U8,4,1)),VC!A1:B16) -> 5 | AD8: =LOOKUP(HEX2DEC(MID(U8,4,1)),VC!A1:D16) -> 11
B9: =B10+1 -> 18 | C9: =C10 -> 1 | D9: =DEC2HEX(HEX2DEC(D10)+1) -> 42 | E9: =E10+1 -> 114 | F9: =IF(HEX2DEC(D9)>15,IF(HEX2DEC(C9) > 15,CONCATENATE(C9,D9),CONCATENATE("0",C9,D9)),IF(HEX2DEC(C9) > 15,CONCATENATE(C9,"0",D9),CONCATENATE("0",C9,"0",D9))) -> 0142 | G9: =G10 -> 0 | M9: =LOOKUP(HEX2DEC(MID(F9,4,1)),VC!A1:C16) -> 8 | N9: =LOOKUP(HEX2DEC(MID(F9,4,1)),VC!A1:B16) -> 4 | O9: =LOOKUP(HEX2DEC(MID(F9,4,1)),VC!A1:D16) -> 12 | Q9: =Q10+1 -> 42 | R9: =R10 -> 1 | S9: =DEC2HEX(HEX2DEC(S10)+1) -> 5A | T9: =T10+1 -> 138 | U9: =IF(HEX2DEC(S9)>15,IF(HEX2DEC(R9) > 15,CONCATENATE(R9,S9),CONCATENATE("0",R9,S9)),IF(HEX2DEC(R9) > 15,CONCATENATE(R9,"0",S9),CONCATENATE("0",R9,"0",S9))) -> 015A | V9: =V10 -> 0 | AB9: =LOOKUP(HEX2DEC(MID(U9,4,1)),VC!A1:C16) -> 8 | AC9: =LOOKUP(HEX2DEC(MID(U9,4,1)),VC!A1:B16) -> 4 | AD9: =LOOKUP(HEX2DEC(MID(U9,4,1)),VC!A1:D16) -> 10
B10: =B11+1 -> 17 | C10: =C11 -> 1 | D10: =DEC2HEX(HEX2DEC(D11)+1) -> 41 | E10: =E11+1 -> 113 | F10: =IF(HEX2DEC(D10)>15,IF(HEX2DEC(C10) > 15,CONCATENATE(C10,D10),CONCATENATE("0",C10,D10)),IF(HEX2DEC(C10) > 15,CONCATENATE(C10,"0",D10),CONCATENATE("0",C10,"0",D10))) -> 0141 | G10: =G11 -> 0 | M10: =LOOKUP(HEX2DEC(MID(F10,4,1)),VC!A1:C16) -> 9 | N10: =LOOKUP(HEX2DEC(MID(F10,4,1)),VC!A1:B16) -> 3 | O10: =LOOKUP(HEX2DEC(MID(F10,4,1)),VC!A1:D16) -> 11 | Q10: =Q11+1 -> 41 | R10: =R11 -> 1 | S10: =DEC2HEX(HEX2DEC(S11)+1) -> 59 | T10: =T11+1 -> 137 | U10: =IF(HEX2DEC(S10)>15,IF(HEX2DEC(R10) > 15,CONCATENATE(R10,S10),CONCATENATE("0",R10,S10)),IF(HEX2DEC(R10) > 15,CONCATENATE(R10,"0",S10),CONCATENATE("0",R10,"0",S10))) -> 0159 | V10: =V11 -> 0 | AB10: =LOOKUP(HEX2DEC(MID(U10,4,1)),VC!A1:C16) -> 9 | AC10: =LOOKUP(HEX2DEC(MID(U10,4,1)),VC!A1:B16) -> 3 | AD10: =LOOKUP(HEX2DEC(MID(U10,4,1)),VC!A1:D16) -> 14
B11: =B12+1 -> 16 | C11: =C12 -> 1 | D11: =DEC2HEX(HEX2DEC(D12)+1) -> 40 | E11: =E12+1 -> 112 | F11: =IF(HEX2DEC(D11)>15,IF(HEX2DEC(C11) > 15,CONCATENATE(C11,D11),CONCATENATE("0",C11,D11)),IF(HEX2DEC(C11) > 15,CONCATENATE(C11,"0",D11),CONCATENATE("0",C11,"0",D11))) -> 0140 | G11: =G12 -> 0 | M11: =LOOKUP(HEX2DEC(MID(F11,4,1)),VC!A1:C16) -> 8 | N11: =LOOKUP(HEX2DEC(MID(F11,4,1)),VC!A1:B16) -> 2 | O11: =LOOKUP(HEX2DEC(MID(F11,4,1)),VC!A1:D16) -> 10 | Q11: =Q12+1 -> 40 | R11: =R12 -> 1 | S11: =DEC2HEX(HEX2DEC(S12)+1) -> 58 | T11: =T12+1 -> 136 | U11: =IF(HEX2DEC(S11)>15,IF(HEX2DEC(R11) > 15,CONCATENATE(R11,S11),CONCATENATE("0",R11,S11)),IF(HEX2DEC(R11) > 15,CONCATENATE(R11,"0",S11),CONCATENATE("0",R11,"0",S11))) -> 0158 | V11: =V12 -> 0 | AB11: =LOOKUP(HEX2DEC(MID(U11,4,1)),VC!A1:C16) -> 8 | AC11: =LOOKUP(HEX2DEC(MID(U11,4,1)),VC!A1:B16) -> 2 | AD11: =LOOKUP(HEX2DEC(MID(U11,4,1)),VC!A1:D16) -> 13
B12: =B13+1 -> 15 | C12: =C13 -> 1 | D12: =DEC2HEX(HEX2DEC(D13)+1) -> 3F | E12: =E13+1 -> 111 | F12: =IF(HEX2DEC(D12)>15,IF(HEX2DEC(C12) > 15,CONCATENATE(C12,D12),CONCATENATE("0",C12,D12)),IF(HEX2DEC(C12) > 15,CONCATENATE(C12,"0",D12),CONCATENATE("0",C12,"0",D12))) -> 013F | G12: =G13 -> 0 | M12: =LOOKUP(HEX2DEC(MID(F12,4,1)),VC!A1:C16) -> 9 | N12: =LOOKUP(HEX2DEC(MID(F12,4,1)),VC!A1:B16) -> 5 | O12: =LOOKUP(HEX2DEC(MID(F12,4,1)),VC!A1:D16) -> 10 | Q12: =Q13+1 -> 39 | R12: =R13 -> 1 | S12: =DEC2HEX(HEX2DEC(S13)+1) -> 57 | T12: =T13+1 -> 135 | U12: =IF(HEX2DEC(S12)>15,IF(HEX2DEC(R12) > 15,CONCATENATE(R12,S12),CONCATENATE("0",R12,S12)),IF(HEX2DEC(R12) > 15,CONCATENATE(R12,"0",S12),CONCATENATE("0",R12,"0",S12))) -> 0157 | V12: =V13 -> 0 | AB12: =LOOKUP(HEX2DEC(MID(U12,4,1)),VC!A1:C16) -> 9 | AC12: =LOOKUP(HEX2DEC(MID(U12,4,1)),VC!A1:B16) -> 5 | AD12: =LOOKUP(HEX2DEC(MID(U12,4,1)),VC!A1:D16) -> 12
B13: =B14+1 -> 14 | C13: =C14 -> 1 | D13: =DEC2HEX(HEX2DEC(D14)+1) -> 3E | E13: =E14+1 -> 110 | F13: =IF(HEX2DEC(D13)>15,IF(HEX2DEC(C13) > 15,CONCATENATE(C13,D13),CONCATENATE("0",C13,D13)),IF(HEX2DEC(C13) > 15,CONCATENATE(C13,"0",D13),CONCATENATE("0",C13,"0",D13))) -> 013E | G13: =G14 -> 0 | M13: =LOOKUP(HEX2DEC(MID(F13,4,1)),VC!A1:C16) -> 8 | N13: =LOOKUP(HEX2DEC(MID(F13,4,1)),VC!A1:B16) -> 4 | O13: =LOOKUP(HEX2DEC(MID(F13,4,1)),VC!A1:D16) -> 14 | Q13: =Q14+1 -> 38 | R13: =R14 -> 1 | S13: =DEC2HEX(HEX2DEC(S14)+1) -> 56 | T13: =T14+1 -> 134 | U13: =IF(HEX2DEC(S13)>15,IF(HEX2DEC(R13) > 15,CONCATENATE(R13,S13),CONCATENATE("0",R13,S13)),IF(HEX2DEC(R13) > 15,CONCATENATE(R13,"0",S13),CONCATENATE("0",R13,"0",S13))) -> 0156 | V13: =V14 -> 0 | AB13: =LOOKUP(HEX2DEC(MID(U13,4,1)),VC!A1:C16) -> 8 | AC13: =LOOKUP(HEX2DEC(MID(U13,4,1)),VC!A1:B16) -> 4 | AD13: =LOOKUP(HEX2DEC(MID(U13,4,1)),VC!A1:D16) -> 11
B14: =B15+1 -> 13 | C14: =C15 -> 1 | D14: =DEC2HEX(HEX2DEC(D15)+1) -> 3D | E14: =E15+1 -> 109 | F14: =IF(HEX2DEC(D14)>15,IF(HEX2DEC(C14) > 15,CONCATENATE(C14,D14),CONCATENATE("0",C14,D14)),IF(HEX2DEC(C14) > 15,CONCATENATE(C14,"0",D14),CONCATENATE("0",C14,"0",D14))) -> 013D | G14: =G15 -> 0 | M14: =LOOKUP(HEX2DEC(MID(F14,4,1)),VC!A1:C16) -> 9 | N14: =LOOKUP(HEX2DEC(MID(F14,4,1)),VC!A1:B16) -> 3 | O14: =LOOKUP(HEX2DEC(MID(F14,4,1)),VC!A1:D16) -> 13 | Q14: =Q15+1 -> 37 | R14: =R15 -> 1 | S14: =DEC2HEX(HEX2DEC(S15)+1) -> 55 | T14: =T15+1 -> 133 | U14: =IF(HEX2DEC(S14)>15,IF(HEX2DEC(R14) > 15,CONCATENATE(R14,S14),CONCATENATE("0",R14,S14)),IF(HEX2DEC(R14) > 15,CONCATENATE(R14,"0",S14),CONCATENATE("0",R14,"0",S14))) -> 0155 | V14: =V15 -> 0 | AB14: =LOOKUP(HEX2DEC(MID(U14,4,1)),VC!A1:C16) -> 9 | AC14: =LOOKUP(HEX2DEC(MID(U14,4,1)),VC!A1:B16) -> 3 | AD14: =LOOKUP(HEX2DEC(MID(U14,4,1)),VC!A1:D16) -> 10
B15: =B16+1 -> 12 | C15: =C16 -> 1 | D15: =DEC2HEX(HEX2DEC(D16)+1) -> 3C | E15: =E16+1 -> 108 | F15: =IF(HEX2DEC(D15)>15,IF(HEX2DEC(C15) > 15,CONCATENATE(C15,D15),CONCATENATE("0",C15,D15)),IF(HEX2DEC(C15) > 15,CONCATENATE(C15,"0",D15),CONCATENATE("0",C15,"0",D15))) -> 013C | G15: =G16 -> 0 | M15: =LOOKUP(HEX2DEC(MID(F15,4,1)),VC!A1:C16) -> 8 | N15: =LOOKUP(HEX2DEC(MID(F15,4,1)),VC!A1:B16) -> 2 | O15: =LOOKUP(HEX2DEC(MID(F15,4,1)),VC!A1:D16) -> 12 | Q15: =Q16+1 -> 36 | R15: =R16 -> 1 | S15: =DEC2HEX(HEX2DEC(S16)+1) -> 54 | T15: =T16+1 -> 132 | U15: =IF(HEX2DEC(S15)>15,IF(HEX2DEC(R15) > 15,CONCATENATE(R15,S15),CONCATENATE("0",R15,S15)),IF(HEX2DEC(R15) > 15,CONCATENATE(R15,"0",S15),CONCATENATE("0",R15,"0",S15))) -> 0154 | V15: =V16 -> 0 | AB15: =LOOKUP(HEX2DEC(MID(U15,4,1)),VC!A1:C16) -> 8 | AC15: =LOOKUP(HEX2DEC(MID(U15,4,1)),VC!A1:B16) -> 2 | AD15: =LOOKUP(HEX2DEC(MID(U15,4,1)),VC!A1:D16) -> 14
B16: =B17+1 -> 11 | C16: =C17 -> 1 | D16: =DEC2HEX(HEX2DEC(D17)+1) -> 3B | E16: =E17+1 -> 107 | F16: =IF(HEX2DEC(D16)>15,IF(HEX2DEC(C16) > 15,CONCATENATE(C16,D16),CONCATENATE("0",C16,D16)),IF(HEX2DEC(C16) > 15,CONCATENATE(C16,"0",D16),CONCATENATE("0",C16,"0",D16))) -> 013B | G16: =G17 -> 0 | M16: =LOOKUP(HEX2DEC(MID(F16,4,1)),VC!A1:C16) -> 9 | N16: =LOOKUP(HEX2DEC(MID(F16,4,1)),VC!A1:B16) -> 5 | O16: =LOOKUP(HEX2DEC(MID(F16,4,1)),VC!A1:D16) -> 11 | Q16: =Q17+1 -> 35 | R16: =R17 -> 1 | S16: =DEC2HEX(HEX2DEC(S17)+1) -> 53 | T16: =T17+1 -> 131 | U16: =IF(HEX2DEC(S16)>15,IF(HEX2DEC(R16) > 15,CONCATENATE(R16,S16),CONCATENATE("0",R16,S16)),IF(HEX2DEC(R16) > 15,CONCATENATE(R16,"0",S16),CONCATENATE("0",R16,"0",S16))) -> 0153 | V16: =V17 -> 0 | AB16: =LOOKUP(HEX2DEC(MID(U16,4,1)),VC!A1:C16) -> 9 | AC16: =LOOKUP(HEX2DEC(MID(U16,4,1)),VC!A1:B16) -> 5 | AD16: =LOOKUP(HEX2DEC(MID(U16,4,1)),VC!A1:D16) -> 13
B17: =B18+1 -> 10 | C17: =C18 -> 1 | D17: =DEC2HEX(HEX2DEC(D18)+1) -> 3A | E17: =E18+1 -> 106 | F17: =IF(HEX2DEC(D17)>15,IF(HEX2DEC(C17) > 15,CONCATENATE(C17,D17),CONCATENATE("0",C17,D17)),IF(HEX2DEC(C17) > 15,CONCATENATE(C17,"0",D17),CONCATENATE("0",C17,"0",D17))) -> 013A | G17: =G18 -> 0 | M17: =LOOKUP(HEX2DEC(MID(F17,4,1)),VC!A1:C16) -> 8 | N17: =LOOKUP(HEX2DEC(MID(F17,4,1)),VC!A1:B16) -> 4 | O17: =LOOKUP(HEX2DEC(MID(F17,4,1)),VC!A1:D16) -> 10 | Q17: =Q18+1 -> 34 | R17: =R18 -> 1 | S17: =DEC2HEX(HEX2DEC(S18)+1) -> 52 | T17: =T18+1 -> 130 | U17: =IF(HEX2DEC(S17)>15,IF(HEX2DEC(R17) > 15,CONCATENATE(R17,S17),CONCATENATE("0",R17,S17)),IF(HEX2DEC(R17) > 15,CONCATENATE(R17,"0",S17),CONCATENATE("0",R17,"0",S17))) -> 0152 | V17: =V18 -> 0 | AB17: =LOOKUP(HEX2DEC(MID(U17,4,1)),VC!A1:C16) -> 8 | AC17: =LOOKUP(HEX2DEC(MID(U17,4,1)),VC!A1:B16) -> 4 | AD17: =LOOKUP(HEX2DEC(MID(U17,4,1)),VC!A1:D16) -> 12
B18: =B19+1 -> 9 | C18: =C19 -> 1 | D18: =DEC2HEX(HEX2DEC(D19)+1) -> 39 | E18: =E19+1 -> 105 | F18: =IF(HEX2DEC(D18)>15,IF(HEX2DEC(C18) > 15,CONCATENATE(C18,D18),CONCATENATE("0",C18,D18)),IF(HEX2DEC(C18) > 15,CONCATENATE(C18,"0",D18),CONCATENATE("0",C18,"0",D18))) -> 0139 | G18: =G19 -> 0 | M18: =LOOKUP(HEX2DEC(MID(F18,4,1)),VC!A1:C16) -> 9 | N18: =LOOKUP(HEX2DEC(MID(F18,4,1)),VC!A1:B16) -> 3 | O18: =LOOKUP(HEX2DEC(MID(F18,4,1)),VC!A1:D16) -> 14 | Q18: =Q19+1 -> 33 | R18: =R19 -> 1 | S18: =DEC2HEX(HEX2DEC(S19)+1) -> 51 | T18: =T19+1 -> 129 | U18: =IF(HEX2DEC(S18)>15,IF(HEX2DEC(R18) > 15,CONCATENATE(R18,S18),CONCATENATE("0",R18,S18)),IF(HEX2DEC(R18) > 15,CONCATENATE(R18,"0",S18),CONCATENATE("0",R18,"0",S18))) -> 0151 | V18: =V19 -> 0 | AB18: =LOOKUP(HEX2DEC(MID(U18,4,1)),VC!A1:C16) -> 9 | AC18: =LOOKUP(HEX2DEC(MID(U18,4,1)),VC!A1:B16) -> 3 | AD18: =LOOKUP(HEX2DEC(MID(U18,4,1)),VC!A1:D16) -> 11
B19: =B20+1 -> 8 | C19: =C20 -> 1 | D19: =DEC2HEX(HEX2DEC(D20)+1) -> 38 | E19: =E20+1 -> 104 | F19: =IF(HEX2DEC(D19)>15,IF(HEX2DEC(C19) > 15,CONCATENATE(C19,D19),CONCATENATE("0",C19,D19)),IF(HEX2DEC(C19) > 15,CONCATENATE(C19,"0",D19),CONCATENATE("0",C19,"0",D19))) -> 0138 | G19: =G20 -> 0 | M19: =LOOKUP(HEX2DEC(MID(F19,4,1)),VC!A1:C16) -> 8 | N19: =LOOKUP(HEX2DEC(MID(F19,4,1)),VC!A1:B16) -> 2 | O19: =LOOKUP(HEX2DEC(MID(F19,4,1)),VC!A1:D16) -> 13 | Q19: =Q20+1 -> 32 | R19: =R20 -> 1 | S19: =DEC2HEX(HEX2DEC(S20)+1) -> 50 | T19: =T20+1 -> 128 | U19: =IF(HEX2DEC(S19)>15,IF(HEX2DEC(R19) > 15,CONCATENATE(R19,S19),CONCATENATE("0",R19,S19)),IF(HEX2DEC(R19) > 15,CONCATENATE(R19,"0",S19),CONCATENATE("0",R19,"0",S19))) -> 0150 | V19: =V20 -> 0 | AB19: =LOOKUP(HEX2DEC(MID(U19,4,1)),VC!A1:C16) -> 8 | AC19: =LOOKUP(HEX2DEC(MID(U19,4,1)),VC!A1:B16) -> 2 | AD19: =LOOKUP(HEX2DEC(MID(U19,4,1)),VC!A1:D16) -> 10
B20: =B21+1 -> 7 | C20: =C21 -> 1 | D20: =DEC2HEX(HEX2DEC(D21)+1) -> 37 | E20: =E21+1 -> 103 | F20: =IF(HEX2DEC(D20)>15,IF(HEX2DEC(C20) > 15,CONCATENATE(C20,D20),CONCATENATE("0",C20,D20)),IF(HEX2DEC(C20) > 15,CONCATENATE(C20,"0",D20),CONCATENATE("0",C20,"0",D20))) -> 0137 | G20: =G21 -> 0 | M20: =LOOKUP(HEX2DEC(MID(F20,4,1)),VC!A1:C16) -> 9 | N20: =LOOKUP(HEX2DEC(MID(F20,4,1)),VC!A1:B16) -> 5 | O20: =LOOKUP(HEX2DEC(MID(F20,4,1)),VC!A1:D16) -> 12 | Q20: =Q21+1 -> 31 | R20: =R21 -> 1 | S20: =DEC2HEX(HEX2DEC(S21)+1) -> 4F | T20: =T21+1 -> 127 | U20: =IF(HEX2DEC(S20)>15,IF(HEX2DEC(R20) > 15,CONCATENATE(R20,S20),CONCATENATE("0",R20,S20)),IF(HEX2DEC(R20) > 15,CONCATENATE(R20,"0",S20),CONCATENATE("0",R20,"0",S20))) -> 014F | V20: =V21 -> 0 | AB20: =LOOKUP(HEX2DEC(MID(U20,4,1)),VC!A1:C16) -> 9 | AC20: =LOOKUP(HEX2DEC(MID(U20,4,1)),VC!A1:B16) -> 5 | AD20: =LOOKUP(HEX2DEC(MID(U20,4,1)),VC!A1:D16) -> 10
B21: =B22+1 -> 6 | C21: =C22 -> 1 | D21: =DEC2HEX(HEX2DEC(D22)+1) -> 36 | E21: =E22+1 -> 102 | F21: =IF(HEX2DEC(D21)>15,IF(HEX2DEC(C21) > 15,CONCATENATE(C21,D21),CONCATENATE("0",C21,D21)),IF(HEX2DEC(C21) > 15,CONCATENATE(C21,"0",D21),CONCATENATE("0",C21,"0",D21))) -> 0136 | G21: =G22 -> 0 | M21: =LOOKUP(HEX2DEC(MID(F21,4,1)),VC!A1:C16) -> 8 | N21: =LOOKUP(HEX2DEC(MID(F21,4,1)),VC!A1:B16) -> 4 | O21: =LOOKUP(HEX2DEC(MID(F21,4,1)),VC!A1:D16) -> 11 | Q21: =Q22+1 -> 30 | R21: =R22 -> 1 | S21: =DEC2HEX(HEX2DEC(S22)+1) -> 4E | T21: =T22+1 -> 126 | U21: =IF(HEX2DEC(S21)>15,IF(HEX2DEC(R21) > 15,CONCATENATE(R21,S21),CONCATENATE("0",R21,S21)),IF(HEX2DEC(R21) > 15,CONCATENATE(R21,"0",S21),CONCATENATE("0",R21,"0",S21))) -> 014E | V21: =V22 -> 0 | AB21: =LOOKUP(HEX2DEC(MID(U21,4,1)),VC!A1:C16) -> 8 | AC21: =LOOKUP(HEX2DEC(MID(U21,4,1)),VC!A1:B16) -> 4 | AD21: =LOOKUP(HEX2DEC(MID(U21,4,1)),VC!A1:D16) -> 14
B22: =B23+1 -> 5 | C22: =C23 -> 1 | D22: =DEC2HEX(HEX2DEC(D23)+1) -> 35 | E22: =E23+1 -> 101 | F22: =IF(HEX2DEC(D22)>15,IF(HEX2DEC(C22) > 15,CONCATENATE(C22,D22),CONCATENATE("0",C22,D22)),IF(HEX2DEC(C22) > 15,CONCATENATE(C22,"0",D22),CONCATENATE("0",C22,"0",D22))) -> 0135 | G22: =G23 -> 0 | M22: =LOOKUP(HEX2DEC(MID(F22,4,1)),VC!A1:C16) -> 9 | N22: =LOOKUP(HEX2DEC(MID(F22,4,1)),VC!A1:B16) -> 3 | O22: =LOOKUP(HEX2DEC(MID(F22,4,1)),VC!A1:D16) -> 10 | Q22: =Q23+1 -> 29 | R22: =R23 -> 1 | S22: =DEC2HEX(HEX2DEC(S23)+1) -> 4D | T22: =T23+1 -> 125 | U22: =IF(HEX2DEC(S22)>15,IF(HEX2DEC(R22) > 15,CONCATENATE(R22,S22),CONCATENATE("0",R22,S22)),IF(HEX2DEC(R22) > 15,CONCATENATE(R22,"0",S22),CONCATENATE("0",R22,"0",S22))) -> 014D | V22: =V23 -> 0 | AB22: =LOOKUP(HEX2DEC(MID(U22,4,1)),VC!A1:C16) -> 9 | AC22: =LOOKUP(HEX2DEC(MID(U22,4,1)),VC!A1:B16) -> 3 | AD22: =LOOKUP(HEX2DEC(MID(U22,4,1)),VC!A1:D16) -> 13
B23: =B24+1 -> 4 | C23: =C24 -> 1 | D23: =DEC2HEX(HEX2DEC(D24)+1) -> 34 | E23: =E24+1 -> 100 | F23: =IF(HEX2DEC(D23)>15,IF(HEX2DEC(C23) > 15,CONCATENATE(C23,D23),CONCATENATE("0",C23,D23)),IF(HEX2DEC(C23) > 15,CONCATENATE(C23,"0",D23),CONCATENATE("0",C23,"0",D23))) -> 0134 | G23: =G24 -> 0 | M23: =LOOKUP(HEX2DEC(MID(F23,4,1)),VC!A1:C16) -> 8 | N23: =LOOKUP(HEX2DEC(MID(F23,4,1)),VC!A1:B16) -> 2 | O23: =LOOKUP(HEX2DEC(MID(F23,4,1)),VC!A1:D16) -> 14 | Q23: =Q24+1 -> 28 | R23: =R24 -> 1 | S23: =DEC2HEX(HEX2DEC(S24)+1) -> 4C | T23: =T24+1 -> 124 | U23: =IF(HEX2DEC(S23)>15,IF(HEX2DEC(R23) > 15,CONCATENATE(R23,S23),CONCATENATE("0",R23,S23)),IF(HEX2DEC(R23) > 15,CONCATENATE(R23,"0",S23),CONCATENATE("0",R23,"0",S23))) -> 014C | V23: =V24 -> 0 | AB23: =LOOKUP(HEX2DEC(MID(U23,4,1)),VC!A1:C16) -> 8 | AC23: =LOOKUP(HEX2DEC(MID(U23,4,1)),VC!A1:B16) -> 2 | AD23: =LOOKUP(HEX2DEC(MID(U23,4,1)),VC!A1:D16) -> 12
B24: =B25+1 -> 3 | C24: =C25 -> 1 | D24: =DEC2HEX(HEX2DEC(D25)+1) -> 33 | E24: =E25+1 -> 99 | F24: =IF(HEX2DEC(D24)>15,IF(HEX2DEC(C24) > 15,CONCATENATE(C24,D24),CONCATENATE("0",C24,D24)),IF(HEX2DEC(C24) > 15,CONCATENATE(C24,"0",D24),CONCATENATE("0",C24,"0",D24))) -> 0133 | G24: =G25 -> 0 | M24: =LOOKUP(HEX2DEC(MID(F24,4,1)),VC!A1:C16) -> 9 | N24: =LOOKUP(HEX2DEC(MID(F24,4,1)),VC!A1:B16) -> 5 | O24: =LOOKUP(HEX2DEC(MID(F24,4,1)),VC!A1:D16) -> 13 | Q24: =Q25+1 -> 27 | R24: =R25 -> 1 | S24: =DEC2HEX(HEX2DEC(S25)+1) -> 4B | T24: =T25+1 -> 123 | U24: =IF(HEX2DEC(S24)>15,IF(HEX2DEC(R24) > 15,CONCATENATE(R24,S24),CONCATENATE("0",R24,S24)),IF(HEX2DEC(R24) > 15,CONCATENATE(R24,"0",S24),CONCATENATE("0",R24,"0",S24))) -> 014B | V24: =V25 -> 0 | AB24: =LOOKUP(HEX2DEC(MID(U24,4,1)),VC!A1:C16) -> 9 | AC24: =LOOKUP(HEX2DEC(MID(U24,4,1)),VC!A1:B16) -> 5 | AD24: =LOOKUP(HEX2DEC(MID(U24,4,1)),VC!A1:D16) -> 11
B25: =B26+1 -> 2 | C25: =C26 -> 1 | D25: =DEC2HEX(HEX2DEC(D26)+1) -> 32 | E25: =E26+1 -> 98 | F25: =IF(HEX2DEC(D25)>15,IF(HEX2DEC(C25) > 15,CONCATENATE(C25,D25),CONCATENATE("0",C25,D25)),IF(HEX2DEC(C25) > 15,CONCATENATE(C25,"0",D25),CONCATENATE("0",C25,"0",D25))) -> 0132 | G25: =G26 -> 0 | M25: =LOOKUP(HEX2DEC(MID(F25,4,1)),VC!A1:C16) -> 8 | N25: =LOOKUP(HEX2DEC(MID(F25,4,1)),VC!A1:B16) -> 4 | O25: =LOOKUP(HEX2DEC(MID(F25,4,1)),VC!A1:D16) -> 12 | Q25: =Q26+1 -> 26 | R25: =R26 -> 1 | S25: =DEC2HEX(HEX2DEC(S26)+1) -> 4A | T25: =T26+1 -> 122 | U25: =IF(HEX2DEC(S25)>15,IF(HEX2DEC(R25) > 15,CONCATENATE(R25,S25),CONCATENATE("0",R25,S25)),IF(HEX2DEC(R25) > 15,CONCATENATE(R25,"0",S25),CONCATENATE("0",R25,"0",S25))) -> 014A | V25: =V26 -> 0 | AB25: =LOOKUP(HEX2DEC(MID(U25,4,1)),VC!A1:C16) -> 8 | AC25: =LOOKUP(HEX2DEC(MID(U25,4,1)),VC!A1:B16) -> 4 | AD25: =LOOKUP(HEX2DEC(MID(U25,4,1)),VC!A1:D16) -> 10
B26: =B27+1 -> 1 | C26: =C27 -> 1 | D26: =DEC2HEX(HEX2DEC(D27)+1) -> 31 | E26: =E27+1 -> 97 | F26: =IF(HEX2DEC(D26)>15,IF(HEX2DEC(C26) > 15,CONCATENATE(C26,D26),CONCATENATE("0",C26,D26)),IF(HEX2DEC(C26) > 15,CONCATENATE(C26,"0",D26),CONCATENATE("0",C26,"0",D26))) -> 0131 | G26: =G27 -> 0 | M26: =LOOKUP(HEX2DEC(MID(F26,4,1)),VC!A1:C16) -> 9 | N26: =LOOKUP(HEX2DEC(MID(F26,4,1)),VC!A1:B16) -> 3 | O26: =LOOKUP(HEX2DEC(MID(F26,4,1)),VC!A1:D16) -> 11 | Q26: =Q27+1 -> 25 | R26: =R27 -> 1 | S26: =DEC2HEX(HEX2DEC(S27)+1) -> 49 | T26: =T27+1 -> 121 | U26: =IF(HEX2DEC(S26)>15,IF(HEX2DEC(R26) > 15,CONCATENATE(R26,S26),CONCATENATE("0",R26,S26)),IF(HEX2DEC(R26) > 15,CONCATENATE(R26,"0",S26),CONCATENATE("0",R26,"0",S26))) -> 0149 | V26: =V27 -> 0 | AB26: =LOOKUP(HEX2DEC(MID(U26,4,1)),VC!A1:C16) -> 9 | AC26: =LOOKUP(HEX2DEC(MID(U26,4,1)),VC!A1:B16) -> 3 | AD26: =LOOKUP(HEX2DEC(MID(U26,4,1)),VC!A1:D16) -> 14
B27: 0 | C27: ='Slot 3'!R4 -> 1 | D27: =DEC2HEX(HEX2DEC('Slot 3'!S4)+1) -> 30 | E27: 96 | F27: =IF(HEX2DEC(D27)>15,IF(HEX2DEC(C27) > 15,CONCATENATE(C27,D27),CONCATENATE("0",C27,D27)),IF(HEX2DEC(C27) > 15,CONCATENATE(C27,"0",D27),CONCATENATE("0",C27,"0",D27))) -> 0130 | G27: ='Slot 3'!V4 -> 0 | M27: =LOOKUP(HEX2DEC(MID(F27,4,1)),VC!A1:C16) -> 8 | N27: =LOOKUP(HEX2DEC(MID(F27,4,1)),VC!A1:B16) -> 2 | O27: =LOOKUP(HEX2DEC(MID(F27,4,1)),VC!A1:D16) -> 10 | Q27: =B4+1 -> 24 | R27: =C4 -> 1 | S27: =DEC2HEX(HEX2DEC(D4)+1) -> 48 | T27: =E4+1 -> 120 | U27: =IF(HEX2DEC(S27)>15,IF(HEX2DEC(R27) > 15,CONCATENATE(R27,S27),CONCATENATE("0",R27,S27)),IF(HEX2DEC(R27) > 15,CONCATENATE(R27,"0",S27),CONCATENATE("0",R27,"0",S27))) -> 0148 | V27: =G4 -> 0 | AB27: =LOOKUP(HEX2DEC(MID(U27,4,1)),VC!A1:C16) -> 8 | AC27: =LOOKUP(HEX2DEC(MID(U27,4,1)),VC!A1:B16) -> 2 | AD27: =LOOKUP(HEX2DEC(MID(U27,4,1)),VC!A1:D16) -> 13
F29: ASIC 0
F31: ASIC 1

Sheet Slot 5
B1: SLOT 5
B2: Port | C2: Index | D2: FID | E2: Start Enable | F2: CLI | G2: End Enable | H2: ICL Description | I2: Port Name | K2: Port | L2: Index | M2: FID | N2: Start Enable | O2: CLI | P2: End Enable | Q2: ICL Description | R2: Port Name
B4: =B5+1 -> 15 | C4: =C5+1 -> 399 | D4: =D5 -> 128 | K4: =K5+1 -> 31 | L4: =L5+1 -> 415 | M4: =M5 -> 128
